<?xml version="1.0"?>
<robot name="RB_Y1_V1.0.1">
  <mobile wheel_base="0.53" wheel_radius="0.1" />

  <link name="base">
    <inertial>
      <mass value="60.08042639"/>
      <origin rpy="0 0 0" xyz="-0.06157942 -0.00142271 0.13513861"/>
      <inertia ixx="1.37742174" ixy="0.02521789" ixz="0.18565467" iyy="2.99386515" iyz="-0.00641869"
               izz="3.76085052"/>
    </inertial>

    <visual>
      <geometry>
        <mesh filename="./meshes/base.stl"/>
      </geometry>
      <material name="LightGrey">
        <color rgba="0.7 0.7 0.7 1.0"/>
      </material>
    </visual>
  </link>

  <link name="wheel_r">
    <inertial>
      <mass value="1.37783736"/>
      <origin rpy="0 0 0" xyz="0.0 -0.00073938 0.0"/>
      <inertia ixx="0.00426657" ixy="0.0" ixz="0.0" iyy="0.00811815" iyz="0.0" izz="0.00426657"/>
    </inertial>

    <visual>
      <geometry>
        <mesh filename="./meshes/WHEEL.stl"/>
      </geometry>
      <material name="LightGrey">
        <color rgba="0.7 0.7 0.7 1.0"/>
      </material>
    </visual>
  </link>

  <link name="wheel_l">
    <inertial>
      <mass value="1.37783736"/>
      <origin rpy="0 0 0" xyz="0.0 0.00073938 0.0"/>
      <inertia ixx="0.00426657" ixy="0.0" ixz="0.0" iyy="0.00811815" iyz="0.0" izz="0.00426657"/>
    </inertial>

    <visual>
      <geometry>
        <mesh filename="./meshes/WHEEL.stl"/>
      </geometry>
      <material name="LightGrey">
        <color rgba="0.7 0.7 0.7 1.0"/>
      </material>
    </visual>
  </link>

  <link name="link_torso_0">
    <inertial>
      <mass value="2.24282123"/>
      <origin rpy="0 0 0" xyz="-0.08848415 0.00021367 0.00000046"/>
      <inertia ixx="0.01413496" ixy="0.00092982" ixz="-0.00000010" iyy="0.01005357"
               iyz="-0.00000008" izz="0.01892525"/>
    </inertial>

    <visual>
      <geometry>
        <mesh filename="./meshes/LINK_1.stl"/>
      </geometry>
      <material name="LightGrey">
        <color rgba="0.7 0.7 0.7 1.0"/>
      </material>
    </visual>

    <collision>
      <geometry>
        <capsule sp="0.0 0.0 0.0" ep="-0.230 0.0 0.0" radius="0.105"/>
      </geometry>
    </collision>
  </link>

  <link name="link_torso_1">
    <inertial>
      <mass value="9.72162676"/>
      <origin rpy="0 0 0" xyz="0.00728955 -0.01728522 0.06911380"/>
      <inertia ixx="0.14862640" ixy="-0.00142621" ixz="-0.00951385" iyy="0.13854733"
               iyz="-0.00975351" izz="0.02912982"/>
    </inertial>

    <visual>
      <geometry>
        <mesh filename="./meshes/LINK_2.stl"/>
      </geometry>
      <material name="LightGrey">
        <color rgba="0.7 0.7 0.7 1.0"/>
      </material>
    </visual>

    <collision>
      <geometry>
        <capsule sp="0.01 0.0 0.130" ep="0.01 0.0 0.350" radius="0.115"/>
      </geometry>
    </collision>
  </link>

  <link name="link_torso_2">
    <inertial>
      <mass value="9.21691850"/>
      <origin rpy="0 0 0" xyz="0.00653835 -0.01769536 0.05636582"/>
      <inertia ixx="0.12162270" ixy="-0.00127910" ixz="-0.00831678" iyy="0.11589190"
               iyz="-0.00873271" izz="0.03094484"/>
    </inertial>

    <visual>
      <geometry>
        <mesh filename="./meshes/LINK_3.stl"/>
      </geometry>
      <material name="LightGrey">
        <color rgba="0.7 0.7 0.7 1.0"/>
      </material>
    </visual>

    <collision>
      <geometry>
        <capsule sp="0.025 0.0 0.15" ep="0.025 0.0 0.310" radius="0.095"/>
      </geometry>
    </collision>
  </link>

  <link name="link_torso_3">
    <inertial>
      <mass value="4.18679196"/>
      <origin rpy="0 0 0" xyz="-0.00574156 -0.01725975 0.00005610"/>
      <inertia ixx="0.00849870" ixy="0.00040861" ixz="-0.00000263" iyy="0.00929513"
               iyz="-0.00001243" izz="0.00955442"/>
    </inertial>

    <visual>
      <geometry>
        <mesh filename="./meshes/LINK_4.stl"/>
      </geometry>
      <material name="LightGrey">
        <color rgba="0.7 0.7 0.7 1.0"/>
      </material>
    </visual>
  </link>

  <link name="link_torso_4">
    <inertial>
      <mass value="4.45566276"/>
      <origin rpy="0 0 0" xyz="-0.09097095 0.00005085 0.02601950"/>
      <inertia ixx="0.01545991" ixy="0.00001883" ixz="-0.00780349" iyy="0.02550888" iyz="0.00000715"
               izz="0.01952563"/>
    </inertial>

    <visual>
      <geometry>
        <mesh filename="./meshes/LINK_5.stl"/>
      </geometry>
      <material name="LightGrey">
        <color rgba="0.7 0.7 0.7 1.0"/>
      </material>
    </visual>

    <collision>
      <geometry>
        <capsule sp="0.03 0.0 0.0385" ep="-0.170 0.0 0.0385" radius="0.105"/>
      </geometry>
    </collision>
  </link>

  <link name="link_torso_5">
    <inertial>
      <mass value="12.87822997"/>
      <origin rpy="0 0 0" xyz="-0.02406094 0.00153804 -0.03247881"/>
      <inertia ixx="0.19092366" ixy="0.00191314" ixz="0.00619094" iyy="0.15535962" iyz="0.00042612"
               izz="0.13368598"/>
    </inertial>

    <visual>
      <geometry>
        <mesh filename="./meshes/LINK_6.stl"/>
      </geometry>
      <material name="LightGrey">
        <color rgba="0.7 0.7 0.7 1.0"/>
      </material>
    </visual>

    <collision>
      <geometry>
        <capsule sp="0.0 0.0 -0.06" ep="0.0 0.0 0.075" radius="0.155"/>
      </geometry>
    </collision>
  </link>

  <link name="link_right_arm_0">
    <inertial>
      <mass value="1.26164242"/>
      <origin rpy="0 0 0" xyz="-0.00316662 0.03437181 -0.00000030"/>
      <inertia ixx="0.00230621" ixy="0.00039024" ixz="-0.00000256" iyy="0.00426418" iyz="0.00000118"
               izz="0.00432156"/>
    </inertial>

    <visual>
      <geometry>
        <mesh filename="./meshes/LINK_7.stl"/>
      </geometry>
      <material name="LightGrey">
        <color rgba="0.7 0.7 0.7 1.0"/>
      </material>
    </visual>
  </link>

  <link name="link_right_arm_1">
    <inertial>
      <mass value="2.27287031"/>
      <origin rpy="0 0 0" xyz="-0.00307855 -0.00124741 -0.01294324"/>
      <inertia ixx="0.00388490" ixy="-0.00001477" ixz="0.00011465" iyy="0.00447034"
               iyz="-0.00010023" izz="0.00288341"/>
    </inertial>

    <visual>
      <geometry>
        <mesh filename="./meshes/LINK_8.stl"/>
      </geometry>
      <material name="LightGrey">
        <color rgba="0.7 0.7 0.7 1.0"/>
      </material>
    </visual>

    <collision>
      <geometry>
        <capsule sp="0.0 0.0 0.0" ep="0.0 0.0 -0.200" radius="0.050"/>
      </geometry>
    </collision>
  </link>

  <link name="link_right_arm_2">
    <inertial>
      <mass value="2.46909439"/>
      <origin rpy="0 0 0" xyz="0.00115434 -0.00196635 -0.16192524"/>
      <inertia ixx="0.00980269" ixy="0.00005871" ixz="0.00051888" iyy="0.00924560" iyz="-0.00045932"
               izz="0.00329867"/>
    </inertial>

    <visual>
      <geometry>
        <mesh filename="./meshes/LINK_9.stl"/>
      </geometry>
      <material name="LightGrey">
        <color rgba="0.7 0.7 0.7 1.0"/>
      </material>
    </visual>

    <collision>
      <geometry>
        <capsule sp="0.026 -0.040 -0.276" ep="0.026 0.040 -0.276" radius="0.05"/>
      </geometry>
    </collision>
  </link>

  <link name="link_right_arm_3">
    <inertial>
      <mass value="2.26099493"/>
      <origin rpy="0 0 0" xyz="-0.01603135 -0.00692891 -0.04549811"/>
      <inertia ixx="0.00822606" ixy="0.00027620" ixz="-0.00156570" iyy="0.00844870" iyz="0.00076157"
               izz="0.00236614"/>
    </inertial>

    <visual>
      <geometry>
        <mesh filename="./meshes/LINK_10.stl"/>
      </geometry>
      <material name="LightGrey">
        <color rgba="0.7 0.7 0.7 1.0"/>
      </material>
    </visual>

    <collision>
      <geometry>
        <capsule sp="-0.031 0.0 -0.05" ep="-0.031 0.0 -0.165" radius="0.04"/>
      </geometry>
    </collision>
  </link>

  <link name="link_right_arm_4">
    <inertial>
      <mass value="0.42508710"/>
      <origin rpy="0 0 0" xyz="-0.00000011 -0.02696036 0.06182110"/>
      <inertia ixx="0.00082466" ixy="0.0" ixz="0.0" iyy="0.00075398" iyz="-0.00025338"
               izz="0.00039794"/>
    </inertial>

    <visual>
      <geometry>
        <mesh filename="./meshes/LINK_11.stl"/>
      </geometry>
      <material name="LightGrey">
        <color rgba="0.7 0.7 0.7 1.0"/>
      </material>
    </visual>

    <collision>
      <geometry>
        <capsule sp="0.0 -0.038 0.065" ep="0.0 -0.038 -0.030" radius="0.035"/>
      </geometry>
    </collision>
  </link>

  <link name="link_right_arm_5">
    <inertial>
      <mass value="1.59194395"/>
      <origin rpy="0 0 0" xyz="0.00318034 -0.00532264 -0.02809655"/>
      <inertia ixx="0.00256054" ixy="-0.00002344" ixz="-0.00001563" iyy="0.00257233"
               iyz="0.00021608" izz="0.00156092"/>
    </inertial>

    <visual>
      <geometry>
        <mesh filename="./meshes/LINK_12.stl"/>
      </geometry>
      <material name="LightGrey">
        <color rgba="0.7 0.7 0.7 1.0"/>
      </material>
    </visual>

    <collision>
      <geometry>
        <capsule sp="0.0 0.0 0.002" ep="0.0 0.0 -0.050" radius="0.075"/>
      </geometry>
    </collision>
  </link>

  <link name="link_right_arm_6">
    <inertial>
      <mass value="0.21029326"/>
      <origin rpy="0 0 0" xyz="0.00071353 -0.00030290 -0.09642180"/>
      <inertia ixx="0.00013433" ixy="-0.00000235" ixz="-0.00000104" iyy="0.00014362"
               iyz="0.00000094" izz="0.00025299"/>
    </inertial>

    <visual>
      <geometry>
        <mesh filename="./meshes/LINK_13.stl"/>
      </geometry>
      <material name="LightGrey">
        <color rgba="0.7 0.7 0.7 1.0"/>
      </material>
    </visual>
  </link>

  <link name="link_left_arm_0">
    <inertial>
      <mass value="1.26164242"/>
      <origin rpy="0 0 0" xyz="-0.00316662 -0.03437151 0.00000242"/>
      <inertia ixx="0.00230624" ixy="-0.00039022" ixz="0.00000269" iyy="0.00426418" iyz="0.00000108"
               izz="0.00432159"/>
    </inertial>

    <visual>
      <geometry>
        <mesh filename="./meshes/LINK_14.stl"/>
      </geometry>
      <material name="LightGrey">
        <color rgba="0.7 0.7 0.7 1.0"/>
      </material>
    </visual>
  </link>

  <link name="link_left_arm_1">
    <inertial>
      <mass value="1.88138658"/>
      <origin rpy="0 0 0" xyz="-0.00183470 0.00040596 -0.01008733"/>
      <inertia ixx="0.00295838" ixy="-0.00001176" ixz="0.00006949" iyy="0.00355208" iyz="0.00004467"
               izz="0.00230558"/>
    </inertial>

    <visual>
      <geometry>
        <mesh filename="./meshes/LINK_15.stl"/>
      </geometry>
      <material name="LightGrey">
        <color rgba="0.7 0.7 0.7 1.0"/>
      </material>
    </visual>

    <collision>
      <geometry>
        <capsule sp="0.0 0.0 0.0" ep="0.0 0.0 -0.200" radius="0.050"/>
      </geometry>
    </collision>
  </link>

  <link name="link_left_arm_2">
    <inertial>
      <mass value="2.35634437"/>
      <origin rpy="0 0 0" xyz="0.00066086 -0.00038583 -0.15742972"/>
      <inertia ixx="0.00842712" ixy="0.00000247" ixz="0.00036948" iyy="0.00802311" iyz="-0.00006550"
               izz="0.00295678"/>
    </inertial>

    <visual>
      <geometry>
        <mesh filename="./meshes/LINK_16.stl"/>
      </geometry>
      <material name="LightGrey">
        <color rgba="0.7 0.7 0.7 1.0"/>
      </material>
    </visual>

    <collision>
      <geometry>
        <capsule sp="0.026 -0.040 -0.276" ep="0.026 0.040 -0.276" radius="0.05"/>
      </geometry>
    </collision>
  </link>

  <link name="link_left_arm_3">
    <inertial>
      <mass value="2.00905891"/>
      <origin rpy="0 0 0" xyz="-0.01565298 0.00793126 -0.04997943"/>
      <inertia ixx="0.00756474" ixy="-0.00026771" ixz="-0.00155419" iyy="0.00772758"
               iyz="-0.00084364" izz="0.00199754"/>
    </inertial>

    <visual>
      <geometry>
        <mesh filename="./meshes/LINK_17.stl"/>
      </geometry>
      <material name="LightGrey">
        <color rgba="0.7 0.7 0.7 1.0"/>
      </material>
    </visual>

    <collision>
      <geometry>
        <capsule sp="-0.031 0.0 -0.05" ep="-0.031 0.0 -0.165" radius="0.04"/>
      </geometry>
    </collision>
  </link>

  <link name="link_left_arm_4">
    <inertial>
      <mass value="0.42508710"/>
      <origin rpy="0 0 0" xyz="0.00000011 0.02696036 0.06182110"/>
      <inertia ixx="0.00082466" ixy="0.0" ixz="0.0" iyy="0.00075398" iyz="0.00025338"
               izz="0.00039794"/>
    </inertial>

    <visual>
      <geometry>
        <mesh filename="./meshes/LINK_18.stl"/>
      </geometry>
      <material name="LightGrey">
        <color rgba="0.7 0.7 0.7 1.0"/>
      </material>
    </visual>

    <collision>
      <geometry>
        <capsule sp="0.0 0.038 0.065" ep="0.0 0.038 -0.030" radius="0.035"/>
      </geometry>
    </collision>
  </link>

  <link name="link_left_arm_5">
    <inertial>
      <mass value="1.44264795"/>
      <origin rpy="0 0 0" xyz="0.00340082 0.00576824 -0.02507309"/>
      <inertia ixx="0.00233577" ixy="0.00003048" ixz="-0.00001191" iyy="0.00232580"
               iyz="-0.00019491" izz="0.00138375"/>
    </inertial>

    <visual>
      <geometry>
        <mesh filename="./meshes/LINK_19.stl"/>
      </geometry>
      <material name="LightGrey">
        <color rgba="0.7 0.7 0.7 1.0"/>
      </material>
    </visual>

    <collision>
      <geometry>
        <capsule sp="0.0 0.0 0.002" ep="0.0 0.0 -0.050" radius="0.075"/>
      </geometry>
    </collision>
  </link>

  <link name="link_left_arm_6">
    <inertial>
      <mass value="0.21029326"/>
      <origin rpy="0 0 0" xyz="-0.00071353 0.00030290 -0.09642180"/>
      <inertia ixx="0.00013433" ixy="-0.00000235" ixz="0.00000104" iyy="0.00014362"
               iyz="-0.00000094" izz="0.00025299"/>
    </inertial>

    <visual>
      <geometry>
        <mesh filename="./meshes/LINK_20.stl"/>
      </geometry>
      <material name="LightGrey">
        <color rgba="0.7 0.7 0.7 1.0"/>
      </material>
    </visual>
  </link>

  <link name="ee_right">
    <inertial>
      <mass value="0.96177521"/>
      <origin rpy="0 0 0" xyz="0.0 0.0 0.0"/>
      <inertia ixx="0.00214634" ixy="0.00000902" ixz="0.00001944" iyy="0.00178176" iyz="-0.00015825"
               izz="0.00131298"/>
    </inertial>

    <visual>
      <geometry>
        <mesh filename="./meshes/EE_BODY.stl"/>
      </geometry>
      <material name="LightGrey">
        <color rgba="0.7 0.7 0.7 1.0"/>
      </material>
    </visual>
  </link>

  <link name="ee_finger_r1">
    <inertial>
      <mass value="0.03030138"/>
      <origin rpy="0 0 0" xyz="0.0 0.0 0.0"/>
      <inertia ixx="0.00000985" ixy="0.0" ixz="-0.00000022" iyy="0.00000845" iyz="0.0"
               izz="0.00000201"/>
    </inertial>

    <visual>
      <geometry>
        <mesh filename="./meshes/EE_FINGER.stl"/>
      </geometry>
      <material name="LightGrey">
        <color rgba="0.7 0.7 0.7 1.0"/>
      </material>
    </visual>
  </link>

  <link name="ee_finger_r2">
    <inertial>
      <mass value="0.03030138"/>
      <origin rpy="0 0 0" xyz="0.0 0.0 0.0"/>
      <inertia ixx="0.00000985" ixy="0.0" ixz="-0.00000022" iyy="0.00000845" iyz="0.0"
               izz="0.00000201"/>
    </inertial>

    <visual>
      <geometry>
        <mesh filename="./meshes/EE_FINGER.stl"/>
      </geometry>
      <material name="LightGrey">
        <color rgba="0.7 0.7 0.7 1.0"/>
      </material>
    </visual>
  </link>

  <link name="ee_left">
    <inertial>
      <mass value="0.96177521"/>
      <origin rpy="0 0 0" xyz="0.0 0.0 0.0"/>
      <inertia ixx="0.00214634" ixy="0.00000902" ixz="0.00001944" iyy="0.00178176" iyz="-0.00015825"
               izz="0.00131298"/>
    </inertial>

    <visual>
      <geometry>
        <mesh filename="./meshes/EE_BODY.stl"/>
      </geometry>
      <material name="LightGrey">
        <color rgba="0.7 0.7 0.7 1.0"/>
      </material>
    </visual>
  </link>

  <link name="ee_finger_l1">
    <inertial>
      <mass value="0.03030138"/>
      <origin rpy="0 0 0" xyz="0.0 0.0 0.0"/>
      <inertia ixx="0.00000985" ixy="0.0" ixz="-0.00000022" iyy="0.00000845" iyz="0.0"
               izz="0.00000201"/>
    </inertial>

    <visual>
      <geometry>
        <mesh filename="./meshes/EE_FINGER.stl"/>
      </geometry>
      <material name="LightGrey">
        <color rgba="0.7 0.7 0.7 1.0"/>
      </material>
    </visual>
  </link>

  <link name="ee_finger_l2">
    <inertial>
      <mass value="0.03030138"/>
      <origin rpy="0 0 0" xyz="0.0 0.0 0.0"/>
      <inertia ixx="0.00000985" ixy="0.0" ixz="-0.00000022" iyy="0.00000845" iyz="0.0"
               izz="0.00000201"/>
    </inertial>

    <visual>
      <geometry>
        <mesh filename="./meshes/EE_FINGER.stl"/>
      </geometry>
      <material name="LightGrey">
        <color rgba="0.7 0.7 0.7 1.0"/>
      </material>
    </visual>
  </link>


  <!-- Joints -->

  <joint name="torso_0" type="revolute">
    <parent link="base"/>
    <child link="link_torso_0"/>
    <origin rpy="0.0 0.0 0.0" xyz="0.0 0.0 0.2805"/>
    <axis xyz="1 0 0"/>
    <limit effort="1000.0" lower="-0.34906585" upper="0.34906585" velocity="3.14159265"/>
  </joint>

  <joint name="torso_1" type="revolute">
    <parent link="link_torso_0"/>
    <child link="link_torso_1"/>
    <origin rpy="0.0 0.0 0.0" xyz="0.0 0.0 0.0"/>
    <axis xyz="0 1 0"/>
    <limit effort="1000.0" lower="-1.04719755" upper="1.52173048" velocity="3.14159265"/>
  </joint>

  <joint name="torso_2" type="revolute">
    <parent link="link_torso_1"/>
    <child link="link_torso_2"/>
    <origin rpy="0.0 0.0 0.0" xyz="0.0 0.0 0.350"/>
    <axis xyz="0 1 0"/>
    <limit effort="1000.0" lower="-2.44346095" upper="1.570796" velocity="3.14159265"/>
  </joint>

  <joint name="torso_3" type="revolute">
    <parent link="link_torso_2"/>
    <child link="link_torso_3"/>
    <origin rpy="0.0 0.0 0.0" xyz="0.0 0.0 0.350"/>
    <axis xyz="0 1 0"/>
    <limit effort="1000.0" lower="-0.78539816" upper="1.57079633" velocity="3.14159265"/>
  </joint>

  <joint name="torso_4" type="revolute">
    <parent link="link_torso_3"/>
    <child link="link_torso_4"/>
    <origin rpy="0.0 0.0 0.0" xyz="0.0 0.0 0.0"/>
    <axis xyz="1 0 0"/>
    <limit effort="1000.0" lower="-0.52359878" upper="0.52359878" velocity="3.14159265"/>
  </joint>

  <joint name="torso_5" type="revolute">
    <parent link="link_torso_4"/>
    <child link="link_torso_5"/>
    <origin rpy="0.0 0.0 0.0" xyz="0.0 0.0 0.309426548461"/>
    <axis xyz="0 0 1"/>
    <limit effort="1000.0" lower="-1.57079633" upper="1.57079633" velocity="3.14159265"/>
  </joint>

  <joint name="right_arm_0" type="revolute">
    <parent link="link_torso_5"/>
    <child link="link_right_arm_0"/>
    <origin rpy="-0.349065850  0.0 0.0" xyz="0.0 -0.220 0.080073451539 "/>
    <axis xyz="0 1 0"/>
    <limit effort="1000.0" lower="-2.35619449" upper="2.35619449" velocity="3.14159265"/>
  </joint>

  <joint name="right_arm_1" type="revolute">
    <parent link="link_right_arm_0"/>
    <child link="link_right_arm_1"/>
    <origin rpy="0.349065850 0.0 0.0" xyz="0.0 0.0 0.0"/>
    <axis xyz="1 0 0"/>
    <limit effort="1000.0" lower="-3.14159265" upper="0.05" velocity="3.14159265"/>
  </joint>

  <joint name="right_arm_2" type="revolute">
    <parent link="link_right_arm_1"/>
    <child link="link_right_arm_2"/>
    <origin rpy="0.0 0.0 0.0" xyz="0.0 0.0 0.0"/>
    <axis xyz="0 0 1"/>
    <limit effort="1000.0" lower="-2.09439510" upper="2.09439510" velocity="3.14159265"/>
  </joint>

  <joint name="right_arm_3" type="revolute">
    <parent link="link_right_arm_2"/>
    <child link="link_right_arm_3"/>
    <origin rpy="0.0 0.0 0.0" xyz="0.031 0.0 -0.276"/>
    <axis xyz="0 1 0"/>
    <limit effort="1000.0" lower="-2.61799388" upper="0.01" velocity="3.14159265"/>
  </joint>

  <joint name="right_arm_4" type="revolute">
    <parent link="link_right_arm_3"/>
    <child link="link_right_arm_4"/>
    <origin rpy="0.0 0.0 0.0" xyz="-0.031 0.0 -0.256"/>
    <axis xyz="0 0 1"/>
    <limit effort="1000.0" lower="-6.28318531" upper="6.28318531" velocity="3.14159265"/>
  </joint>

  <joint name="right_arm_5" type="revolute">
    <parent link="link_right_arm_4"/>
    <child link="link_right_arm_5"/>
    <origin rpy="0.0 0.0 0.0" xyz="0.0 0.0 0.0"/>
    <axis xyz="0 1 0"/>
    <limit effort="1000.0" lower="-1.74532925" upper="2.00712864" velocity="3.14159265"/>
  </joint>

  <joint name="right_arm_6" type="revolute">
    <parent link="link_right_arm_5"/>
    <child link="link_right_arm_6"/>
    <origin rpy="0.0 0.0 0.0" xyz="0.0 0.0 0.0"/>
    <axis xyz="0 0 1"/>
    <limit effort="1000.0" lower="-2.96705973" upper="2.96705973" velocity="3.14159265"/>
  </joint>

  <joint name="left_arm_0" type="revolute">
    <parent link="link_torso_5"/>
    <child link="link_left_arm_0"/>
    <origin rpy="0.349065850  0.0 0.0" xyz="0.0 0.220 0.080073452 "/>
    <axis xyz="0 1 0"/>
    <limit effort="1000.0" lower="-2.35619449" upper="2.35619449" velocity="3.14159265"/>
  </joint>

  <joint name="left_arm_1" type="revolute">
    <parent link="link_left_arm_0"/>
    <child link="link_left_arm_1"/>
    <origin rpy="-0.349065850 0.0 0.0" xyz="0.0 0.0 0.0"/>
    <axis xyz="1 0 0"/>
    <limit effort="1000.0" lower="-0.05" upper="3.14159265" velocity="3.14159265"/>
  </joint>

  <joint name="left_arm_2" type="revolute">
    <parent link="link_left_arm_1"/>
    <child link="link_left_arm_2"/>
    <origin rpy="0.0 0.0 0.0" xyz="0.0 0.0 0.0"/>
    <axis xyz="0 0 1"/>
    <limit effort="1000.0" lower="-2.09439510" upper="2.09439510" velocity="3.14159265"/>
  </joint>

  <joint name="left_arm_3" type="revolute">
    <parent link="link_left_arm_2"/>
    <child link="link_left_arm_3"/>
    <origin rpy="0.0 0.0 0.0" xyz="0.031 0.0 -0.276"/>
    <axis xyz="0 1 0"/>
    <limit effort="1000.0" lower="-2.61799388" upper="0.01" velocity="3.14159265"/>
  </joint>

  <joint name="left_arm_4" type="revolute">
    <parent link="link_left_arm_3"/>
    <child link="link_left_arm_4"/>
    <origin rpy="0.0 0.0 0.0" xyz="-0.031 0.0 -0.256"/>
    <axis xyz="0 0 1"/>
    <limit effort="1000.0" lower="-6.28318531" upper="6.28318531" velocity="3.14159265"/>
  </joint>

  <joint name="left_arm_5" type="revolute">
    <parent link="link_left_arm_4"/>
    <child link="link_left_arm_5"/>
    <origin rpy="0.0 0.0 0.0" xyz="0.0 0.0 0.0"/>
    <axis xyz="0 1 0"/>
    <limit effort="1000.0" lower="-1.74532925" upper="2.00712864" velocity="30.14159265"/>
  </joint>

  <joint name="left_arm_6" type="revolute">
    <parent link="link_left_arm_5"/>
    <child link="link_left_arm_6"/>
    <origin rpy="0.0 0.0 0.0" xyz="0.0 0.0 0.0"/>
    <axis xyz="0 0 1"/>
    <limit effort="1000.0" lower="-2.96705973" upper="2.96705973" velocity="3.14159265"/>
  </joint>

  <joint name="right_wheel" type="continuous">
    <parent link="base"/>
    <child link="wheel_r"/>
    <origin rpy="0.0 0.0 0.0" xyz="0.228 -0.265 0.1"/>
    <axis xyz="0 1 0"/>
  </joint>

  <joint name="left_wheel" type="continuous">
    <parent link="base"/>
    <child link="wheel_l"/>
    <origin rpy="0.0 0.0 0.0" xyz="0.228 0.265 0.1"/>
    <axis xyz="0 1 0"/>
  </joint>

  <joint name="tool_right" type="fixed">
    <parent link="link_right_arm_6"/>
    <child link="ee_right"/>
    <origin rpy="0.0 0.0 0.0" xyz="0.0 0.0 -0.1087"/>
    <axis xyz="0 0 1"/>
  </joint>

  <joint name="gripper_finger_r1" type="fixed">
    <parent link="ee_right"/>
    <child link="ee_finger_r1"/>
    <origin rpy="0.0 0.0 0.0" xyz="0.005 0.0 -0.1191"/>
    <axis xyz="-1 0 0"/>
    <limit effort="1000" velocity="0.05" lower="-0.05" upper="0"/>
  </joint>

  <joint name="gripper_finger_r2" type="fixed">
    <parent link="ee_right"/>
    <child link="ee_finger_r2"/>
    <origin rpy="0.0 0.0 3.1415926535" xyz="-0.005 0.0 -0.1191"/>
    <axis xyz="1 0 0"/>
    <limit effort="1000" velocity="0.05" lower="0" upper="0.05"/>
  </joint>

  <joint name="tool_left" type="fixed">
    <parent link="link_left_arm_6"/>
    <child link="ee_left"/>
    <origin rpy="0.0 0.0 0.0" xyz="0.0 0.0 -0.1087"/>
    <axis xyz="0 0 1"/>
  </joint>

  <joint name="gripper_finger_l1" type="fixed">
    <parent link="ee_left"/>
    <child link="ee_finger_l1"/>
    <origin rpy="0.0 0.0 0.0" xyz="0.005 0.0 -0.1191"/>
    <axis xyz="-1 0 0"/>
    <limit effort="1000" velocity="0.05" lower="-0.05" upper="0"/>
  </joint>

  <joint name="gripper_finger_l2" type="fixed">
    <parent link="ee_left"/>
    <child link="ee_finger_l2"/>
    <origin rpy="0.0 0.0 3.1415926535" xyz="-0.005 0.0 -0.1191"/>
    <axis xyz="1 0 0"/>
    <limit effort="1000" velocity="0.05" lower="0" upper="0.05"/>
  </joint>

</robot>