<mujoco model="rby1m_v1.3">
  <compiler angle="radian" autolimits="true" eulerseq="xyz" />

  <default>
    <joint armature="10" damping="50" range="-3.14 3.14" />
    <material specular="0.5" shininess="0.25" />
  </default>

  <visual>
    <map force="0.1" zfar="30" />
    <rgba haze="0.15 0.25 0.35 1" />
    <quality shadowsize="4096" />
    <global offwidth="800" offheight="800" />
  </visual>

  <asset>
    <texture type="skybox" builtin="gradient" rgb1="0.3 0.5 0.7" rgb2="0 0 0" width="512" height="512" />
    <texture name="plane" type="2d" builtin="checker" rgb1=".2 .3 .4" rgb2=".1 0.15 0.2" width="512" height="512"
      mark="cross" markrgb=".8 .8 .8" />
    <material name="plane" reflectance="0.3" texture="plane" texrepeat="1 1" texuniform="true" />

    <include file="./assets/materials.xml" />
    <include file="./assets/base/assets.xml" />
    <include file="./assets/MECANUM_WHEEL/assets.xml" />
    <include file="./assets/MECANUM_WHEEL_M/assets.xml" />
    <include file="./assets/WHEEL/assets.xml" />
    <include file="./assets/EE_GR_TF/assets.xml" />
    <include file="./assets/EE_FINGER/assets.xml" />
    <include file="./assets/FT_SENSOR_L/assets.xml" />
    <include file="./assets/FT_SENSOR_R/assets.xml" />
    <include file="./assets/LINK_1/assets.xml" />
    <include file="./assets/LINK_2/assets.xml" />
    <include file="./assets/LINK_3/assets.xml" />
    <include file="./assets/LINK_4/assets.xml" />
    <include file="./assets/LINK_5/assets.xml" />
    <include file="./assets/LINK_6/assets.xml" />
    <include file="./assets/LINK_7/assets.xml" />
    <include file="./assets/LINK_8/assets.xml" />
    <include file="./assets/LINK_9/assets.xml" />
    <include file="./assets/LINK_10/assets.xml" />
    <include file="./assets/LINK_11_WY/assets.xml" />
    <include file="./assets/LINK_12_WP/assets.xml" />
    <include file="./assets/LINK_13_WR/assets.xml" />
    <include file="./assets/LINK_14/assets.xml" />
    <include file="./assets/LINK_15/assets.xml" />
    <include file="./assets/LINK_16/assets.xml" />
    <include file="./assets/LINK_17/assets.xml" />
    <include file="./assets/LINK_18_WY/assets.xml" />
    <include file="./assets/LINK_19_WP/assets.xml" />
    <include file="./assets/LINK_20_WR/assets.xml" />
    <include file="./assets/NECK_0/assets.xml" />
    <include file="./assets/NECK_1/assets.xml" />
    <include file="./assets/NECK_2/assets.xml" />
  </asset>

  <worldbody>
    <geom name="floor" pos="0 0 0" size="0 0 .25" type="plane" material="plane" condim="1"
      solimp="0.95 0.99 0.001 0.5 2" friction="0.05 0.001 0.05" />
    <light directional="true" diffuse=".8 .8 .8" specular="0 0 0" pos="0 0 5" dir="0 0 -1" castshadow="false" />

    <body name="base">
      <inertial pos="-0.0615794 -0.00142271 0.135139" quat="0.00383057 0.733861 -0.00742942 0.679248" mass="60.0804" diaginertia="3.77525 2.99424 1.36264" />
      <joint name="world_j" type="free" limited="false" actuatorfrclimited="false" />
      <include file="./assets/base/geoms.xml" />

      <body name="wheel_fr_link" pos="0.243 -0.245 0.076">
        <inertial pos="-0.00010511 0.0009458 0" quat="0.707046 0 0 0.707168" mass="2.5441" diaginertia="0.00616429 0.00470985 0.00470754" />
        <joint name="wheel_fr" pos="0 0 0" axis="0 1 0" limited="false" />
        <include file="./assets/MECANUM_WHEEL/geoms.xml" />
      </body>
      <body name="wheel_fl_link" pos="0.243 0.245 0.076">
        <inertial pos="-0.00010433 -0.00094577 0" quat="0.707168 0 0 0.707046" mass="2.54418" diaginertia="0.00616468 0.00471013 0.00470782" />
        <joint name="wheel_fl" pos="0 0 0" axis="0 1 0" limited="false" />
        <include file="./assets/MECANUM_WHEEL_M/geoms.xml" />
      </body>
      <body name="wheel_rr_link" pos="-0.247 -0.245 0.076">
        <inertial pos="-0.00010511 0.0009458 0" quat="0.707046 0 0 0.707168" mass="2.5441" diaginertia="0.00616429 0.00470985 0.00470754" />
        <joint name="wheel_rr" pos="0 0 0" axis="0 1 0" limited="false" />
        <include file="./assets/MECANUM_WHEEL_M/geoms.xml" />
      </body>
      <body name="wheel_rl_link" pos="-0.247 0.245 0.076">
        <inertial pos="-0.00010433 -0.00094577 0" quat="0.707168 0 0 0.707046" mass="2.54418" diaginertia="0.00616468 0.00471013 0.00470782" />
        <joint name="wheel_rl" pos="0 0 0" axis="0 1 0" limited="false" />
        <include file="./assets/MECANUM_WHEEL/geoms.xml" />
      </body>

      <body name="link_torso_0" pos="0 0 0.2965">
        <inertial pos="-0.0884841 0.00021367 4.6e-07" quat="0.443798 0.550483 -0.443815 0.55049" mass="2.24282" diaginertia="0.0189253 0.0143368 0.00985172" />
        <joint name="torso_0" pos="0 0 0" axis="1 0 0" limited="true" range="-0.261799 0.261799" />
        <include file="./assets/LINK_1/geoms.xml" />
        <geom size="0.105 0.115" pos="-0.115 0 0" quat="0.707105 0 0.707108 0" class="in-model-collision" />

        <body name="link_torso_1">
          <inertial pos="0.00728955 -0.0172852 0.0691138" quat="0.997768 -0.0453891 0.0382115 -0.0306483" mass="9.72163" diaginertia="0.149421 0.139376 0.0275059" />
          <joint name="torso_1" pos="0 0 0" axis="0 1 0" limited="true" range="-0.523599 1.5708" />
          <include file="./assets/LINK_2/geoms.xml" />
          <geom size="0.115 0.11" pos="0.01 0 0.24" class="in-model-collision" />
          <body name="link_torso_2" pos="0 0 0.35">
            <inertial pos="0.00653835 -0.0176954 0.0563658" quat="0.99687 -0.052526 0.0433482 -0.0401474" mass="9.21692" diaginertia="0.12242 0.116748 0.0292915" />
            <joint name="torso_2" pos="0 0 0" axis="0 1 0" limited="true" range="-2.61799 1.5708" />
            <include file="./assets/LINK_3/geoms.xml" />
            <geom size="0.095 0.08" pos="0.025 0 0.23" class="in-model-collision" />
            <body name="link_torso_3" pos="0 0 0.35">
              <inertial pos="-0.00574156 -0.0172598 5.61e-05" quat="0.0913806 0.682262 -0.18841 0.700478" mass="4.18679" diaginertia="0.00955618 0.00946572 0.00832635" />
              <joint name="torso_3" pos="0 0 0" axis="0 1 0" limited="true" range="-0.785398 1.5708" />
              <include file="./assets/LINK_4/geoms.xml" />
              <body name="link_torso_4">
                <inertial pos="-0.0909709 5.085e-05 0.0260195" quat="-0.0536434 0.4399 -0.0270045 0.896036" mass="4.45566" diaginertia="0.0255574 0.0255082 0.00942882" />
                <joint name="torso_4" pos="0 0 0" axis="1 0 0" limited="true" range="-0.523599 0.523599" />
                <include file="./assets/LINK_5/geoms.xml" />
                <geom size="0.105 0.1" pos="-0.07 0 0.0385" quat="0.707105 0 0.707108 0" class="in-model-collision" />
                <body name="link_torso_5" pos="0 0 0.309427">
                  <inertial pos="-0.0317867 0.000717173 -0.0207698" quat="0.984218 -0.0115571 -0.168721 0.0520939" mass="15.3902" diaginertia="0.260312 0.245377 0.182375" />
                  <joint name="torso_5" pos="0 0 0" axis="0 0 1" limited="true" range="-2.35619 2.35619" />
                  <include file="./assets/LINK_6/geoms.xml" />
                  <geom size="0.155 0.0675" pos="0 0 0.0075" class="in-model-collision" />
                  <body name="NECK_0" pos="0.022 0 0.120073">
                    <inertial pos="0 0 0" mass="0" />
                    <include file="./assets/NECK_0/geoms.xml" />
                  </body>
                  <body name="link_right_arm_0" pos="0 -0.22 0.0800735">
                    <inertial pos="-0.00316662 0.0343718 -3e-07" quat="0.536676 0.553304 0.439546 0.461122" mass="1.26164" diaginertia="0.00433912 0.00432154 0.00223129" />
                    <joint name="right_arm_0" pos="0 0 0" axis="0 0.939693 -0.34202" limited="true" range="-3.14159 3.14159" />
                    <include file="./assets/LINK_7/geoms.xml" />
                    <geom size="0.075 0.035" pos="-0.015 0.018 -0.008" quat="0.707105 0 0.707108 0" class="in-model-collision" />
                    <body name="link_right_arm_1">
                      <inertial pos="-0.00307855 -0.00124741 -0.0129432" quat="0.691024 -0.061096 -0.016345 0.72006" mass="2.27287" diaginertia="0.00447747 0.0038967 0.00286448" />
                      <joint name="right_arm_1" pos="0 0 0" axis="1 0 0" limited="true" range="-3.14159 0.0174533" />
                      <include file="./assets/LINK_8/geoms.xml" />
                      <geom size="0.05 0.1" pos="0 0 -0.1" class="in-model-collision" />
                      <body name="link_right_arm_2">
                        <inertial pos="0.00115434 -0.00196635 -0.161925" quat="0.998316 -0.0390505 -0.0388849 0.0181103" mass="2.46909" diaginertia="0.0098447 0.00928024 0.00322202" />
                        <joint name="right_arm_2" pos="0 0 0" axis="0 0 1" limited="true" range="-3.14159 3.14159" />
                        <include file="./assets/LINK_9/geoms.xml" />
                        <geom size="0.05 0.04" pos="0.026 0 -0.276" quat="0.707105 0.707108 0 0" class="in-model-collision" />
                        <body name="link_right_arm_3" pos="0.031 0 -0.276">
                          <inertial pos="-0.0160313 -0.00692891 -0.0454981" quat="0.950945 0.0932571 0.100342 0.277377" mass="2.26099" diaginertia="0.0086724 0.00849326 0.00187523" />
                          <joint name="right_arm_3" pos="0 0 0" axis="0 1 0" limited="true" range="-2.61799 0.0174533" />
                          <include file="./assets/LINK_10/geoms.xml" />
                          <geom size="0.04 0.0575" pos="-0.031 0 -0.1075" class="in-model-collision" />
                          <body name="link_right_arm_4" pos="-0.031 0 -0.3095">
                            <inertial pos="-6.159e-05 0.00402933 0.0953963" quat="0.999907 -0.013359 9.85194e-05 -0.00269294" mass="1.49373" diaginertia="0.00327356 0.00252276 0.00186781" />
                            <joint name="right_arm_4" pos="0 0 0" axis="0 0 1" limited="true" range="-3.14159 3.14159" />
                            <include file="./assets/LINK_11_WY/geoms.xml" />
                            <geom size="0.035 0.0475" pos="0 -0.038 0.0175" class="in-model-collision" />
                            <body name="link_right_arm_5">
                              <inertial pos="0.00178191 0.00092083 6.831e-05" quat="0.0782288 0.706713 -0.0765831 0.69898" mass="0.871638" diaginertia="0.000676215 0.000569165 0.000469831" />
                              <joint name="right_arm_5" pos="0 0 0" axis="0 1 0" limited="true" range="-0.872665 0.872665" />
                              <include file="./assets/LINK_12_WP/geoms.xml" />
                              <geom size="0.075 0.026" pos="0 0 -0.024" class="in-model-collision" />
                              <body name="link_right_arm_6">
                                <inertial pos="0.00447743 -0.00124947 -0.0909663" quat="0.977378 -0.0281029 0.206874 -0.0338593" mass="1.21918" diaginertia="0.0026136 0.00196166 0.00160019" />
                                <joint name="right_arm_6" pos="0 0 0" axis="1 0 0" limited="true" range="-1.5708 1.5708" />
                                <include file="./assets/LINK_13_WR/geoms.xml" />
                                <body name="EE_GR_TF_R" pos="0 0 -0.125" quat="4.48966e-11 1 0 0">
                                  <inertial pos="0 0 0" mass="0" />
                                  <include file="./assets/EE_GR_TF/geoms.xml" />
                                </body>
                                <body name="ee_finger_r1" pos="0 0 -0.125" quat="-0.707107 6.34934e-11 0 0.707107">
                                  <inertial pos="0.00278346 -3.29e-06 -0.0257011" quat="0.999784 0 0.0208044 0" mass="0.03327" diaginertia="1.23275e-05 1.066e-05 2.22251e-06" />
                                  <joint name="gripper_finger_r1" pos="0 0 0" axis="1 0 0" type="slide" limited="true" range="0 0.05" />
                                  <include file="./assets/EE_FINGER/geoms.xml" />
                                </body>
                                <body name="ee_finger_r2" pos="0 0 -0.125" quat="-0.707107 6.34934e-11 0 -0.707107">
                                  <inertial pos="0.00278346 -3.29e-06 -0.0257011" quat="0.999784 0 0.0208044 0" mass="0.03327" diaginertia="1.23275e-05 1.066e-05 2.22251e-06" />
                                  <joint name="gripper_finger_r2" pos="0 0 0" axis="-1 0 0" type="slide" limited="true" range="-0.05 0" />
                                  <include file="./assets/EE_FINGER/geoms.xml" />
                                </body>
                              </body>
                            </body>
                          </body>
                        </body>
                      </body>
                    </body>
                  </body>
                  <body name="link_left_arm_0" pos="0 0.22 0.0800735">
                    <inertial pos="-0.00316662 -0.0343715 2.42e-06" quat="0.441442 0.459281 0.538276 0.551768" mass="1.26164" diaginertia="0.0043391 0.00432158 0.00223133" />
                    <joint name="left_arm_0" pos="0 0 0" axis="0 0.939693 0.34202" limited="true" range="-3.14159 3.14159" />
                    <include file="./assets/LINK_14/geoms.xml" />
                    <geom size="0.075 0.035" pos="-0.015 -0.018 -0.008" quat="0.707105 0 0.707108 0" class="in-model-collision" />
                    <body name="link_left_arm_1">
                      <inertial pos="-0.0018347 0.00040596 -0.0100873" quat="0.701113 -0.0246572 -0.049881 0.710875" mass="1.88139" diaginertia="0.00355382 0.00296561 0.0022966" />
                      <joint name="left_arm_1" pos="0 0 0" axis="1 0 0" limited="true" range="-0.0174533 3.14159" />
                      <include file="./assets/LINK_15/geoms.xml" />
                      <geom size="0.05 0.1" pos="0 0 -0.1" class="in-model-collision" />
                      <body name="link_left_arm_2">
                        <inertial pos="0.00066086 -0.00038583 -0.15743" quat="0.999413 -0.00635373 -0.0335732 -0.00246859" mass="2.35634" diaginertia="0.00845197 0.00802394 0.00293109" />
                        <joint name="left_arm_2" pos="0 0 0" axis="0 0 1" limited="true" range="-3.14159 3.14159" />
                        <include file="./assets/LINK_16/geoms.xml" />
                        <geom size="0.05 0.04" pos="0.026 0 -0.276" quat="0.707105 0.707108 0 0" class="in-model-collision" />
                        <body name="link_left_arm_3" pos="0.031 0 -0.276">
                          <inertial pos="-0.015653 0.00793126 -0.0499794" quat="0.977098 -0.0897025 0.113811 -0.15582" mass="2.00906" diaginertia="0.00798526 0.00783637 0.00146823" />
                          <joint name="left_arm_3" pos="0 0 0" axis="0 1 0" limited="true" range="-2.61799 0.0174533" />
                          <include file="./assets/LINK_17/geoms.xml" />
                          <geom size="0.04 0.0575" pos="-0.031 0 -0.1075" class="in-model-collision" />
                          <body name="link_left_arm_4" pos="-0.031 0 -0.3095">
                            <inertial pos="6.159e-05 -0.00402933 0.0953963" quat="0.999907 0.013359 -9.85194e-05 -0.00269294" mass="1.49373" diaginertia="0.00327356 0.00252276 0.00186781" />
                            <joint name="left_arm_4" pos="0 0 0" axis="0 0 1" limited="true" range="-3.14159 3.14159" />
                            <include file="./assets/LINK_18_WY/geoms.xml" />
                            <geom size="0.035 0.0475" pos="0 0.038 0.0175" class="in-model-collision" />
                            <body name="link_left_arm_5">
                              <inertial pos="0.00178191 0.00092083 6.831e-05" quat="-0.0765831 0.69898 0.0782288 0.706713" mass="0.871638" diaginertia="0.000676215 0.000569165 0.000469831" />
                              <joint name="left_arm_5" pos="0 0 0" axis="0 1 0" limited="true" range="-0.872665 0.872665" />
                              <include file="./assets/LINK_19_WP/geoms.xml" />
                              <geom size="0.075 0.026" pos="0 0 -0.024" class="in-model-collision" />
                              <body name="link_left_arm_6">
                                <inertial pos="0.00447743 -0.00124947 -0.0909663" quat="0.977378 -0.0281029 0.206874 -0.0338593" mass="1.21918" diaginertia="0.0026136 0.00196166 0.00160019" />
                                <joint name="left_arm_6" pos="0 0 0" axis="1 0 0" limited="true" range="-1.5708 1.5708" />
                                <include file="./assets/LINK_20_WR/geoms.xml" />
                                <body name="EE_GR_TF_L" pos="0 0 -0.125" quat="4.48966e-11 1 0 0">
                                  <inertial pos="0 0 0" mass="0" />
                                  <include file="./assets/EE_GR_TF/geoms.xml" />
                                </body>
                                <body name="ee_finger_l1" pos="0 0 -0.125" quat="-0.707107 6.34934e-11 0 0.707107">
                                  <inertial pos="0.00278346 -3.29e-06 -0.0257011" quat="0.999784 0 0.0208044 0" mass="0.03327" diaginertia="1.23275e-05 1.066e-05 2.22251e-06" />
                                  <joint name="gripper_finger_l1" pos="0 0 0" axis="1 0 0" type="slide" limited="true" range="0 0.05" />
                                  <include file="./assets/EE_FINGER/geoms.xml" />
                                </body>
                                <body name="ee_finger_l2" pos="0 0 -0.125" quat="-0.707107 6.34934e-11 0 -0.707107">
                                  <inertial pos="0.00278346 -3.29e-06 -0.0257011" quat="0.999784 0 0.0208044 0" mass="0.03327" diaginertia="1.23275e-05 1.066e-05 2.22251e-06" />
                                  <joint name="gripper_finger_l2" pos="0 0 0" axis="-1 0 0" type="slide" limited="true" range="-0.05 0" />
                                  <include file="./assets/EE_FINGER/geoms.xml" />
                                </body>
                              </body>
                            </body>
                          </body>
                        </body>
                      </body>
                    </body>
                  </body>
                  <body name="link_head_1" pos="0.022 0 0.200073">
                    <inertial pos="-0.00041643 0.00593524 -0.00289916" quat="0.686943 0.726608 -0.0122145 -4.20643e-05" mass="0.704765" diaginertia="0.000662227 0.000593368 0.000359954" />
                    <joint name="head_0" pos="0 0 0" axis="0 0 1" limited="true" range="-1.57 1.57" />
                    <include file="./assets/NECK_1/geoms.xml" />
                    <body name="link_head_2">
                      <inertial pos="0.0531532 0.00547509 0.0591391" quat="0.221288 0.46561 -0.261859 0.815885" mass="0.952627" diaginertia="0.00173533 0.00136285 0.000633984" />
                      <joint name="head_1" pos="0 0 0" axis="0 1 0" limited="true" range="-1.57 1.57" />
                      <include file="./assets/NECK_2/geoms.xml" />
                    </body>
                  </body>
                </body>
              </body>
            </body>
          </body>
        </body>
      </body>
    </body>
  </worldbody>

  <equality>
    <joint name="right_finger" joint1="gripper_finger_r1" joint2="gripper_finger_r2" polycoef="0 -1 0 0 0" />
    <joint name="left_finger" joint1="gripper_finger_l1" joint2="gripper_finger_l2" polycoef="0 -1 0 0 0" />
  </equality>
</mujoco>