<mujoco model="RB_Y1_V1.0.1">
    <compiler angle="radian" meshdir="./meshes/" autolimits="true" eulerseq="xyz"/>
    <option timestep="0.003" solver="CG" iterations="30" tolerance="1e-6"/>
    <size nuserdata="144"/>

    <default>
        <joint armature="10" damping="50" range="-3.14 3.14"/>
        <motor ctrlrange="-3000000 3000000" ctrllimited="true"/>
        <material specular="0.5" shininess="0.25"/>
    </default>

    <asset>
        <texture type="skybox" builtin="gradient" rgb1="0.3 0.5 0.7" rgb2="0 0 0" width="512" height="512"/>
        <texture name="plane" type="2d" builtin="checker" rgb1=".2 .3 .4" rgb2=".1 0.15 0.2" width="512" height="512"
                 mark="cross" markrgb=".8 .8 .8"/>
        <material name="plane" reflectance="0.3" texture="plane" texrepeat="1 1" texuniform="true"/>

        <mesh name="base" file="base.stl"/>
        <mesh name="WHEEL" file="WHEEL.stl"/>
        <mesh name="LINK_1" file="LINK_1.stl"/>
        <mesh name="LINK_2" file="LINK_2.stl"/>
        <mesh name="LINK_3" file="LINK_3.stl"/>
        <mesh name="LINK_4" file="LINK_4.stl"/>
        <mesh name="LINK_5" file="LINK_5.stl"/>
        <mesh name="LINK_6" file="LINK_6.stl"/>
        <mesh name="LINK_7" file="LINK_7.stl"/>
        <mesh name="LINK_8" file="LINK_8.stl"/>
        <mesh name="LINK_9" file="LINK_9.stl"/>
        <mesh name="LINK_10" file="LINK_10.stl"/>
        <mesh name="LINK_11" file="LINK_11.stl"/>
        <mesh name="LINK_12" file="LINK_12.stl"/>
        <mesh name="LINK_13" file="LINK_13.stl"/>
        <mesh name="LINK_14" file="LINK_14.stl"/>
        <mesh name="LINK_15" file="LINK_15.stl"/>
        <mesh name="LINK_16" file="LINK_16.stl"/>
        <mesh name="LINK_17" file="LINK_17.stl"/>
        <mesh name="LINK_18" file="LINK_18.stl"/>
        <mesh name="LINK_19" file="LINK_19.stl"/>
        <mesh name="LINK_20" file="LINK_20.stl"/>
        <mesh name="EE_BODY" file="EE_BODY.stl"/>
        <mesh name="EE_FINGER" file="EE_FINGER.stl"/>
    </asset>

    <visual>
        <map force="0.1" zfar="30"/>
        <rgba haze="0.15 0.25 0.35 1"/>
        <quality shadowsize="4096"/>
        <global offwidth="800" offheight="800"/>
    </visual>

    <worldbody>
        <geom name="floor" pos="0 0 0" size="0 0 .25" type="plane" material="plane" condim="1"
              solimp="0.95 0.99 0.001 0.5 2" friction="0.05 0.001 0.05"/>
        <light directional="true" diffuse=".8 .8 .8" specular="0 0 0" pos="0 0 5" dir="0 0 -1" castshadow="false"/>

        <body name="link_base" pos="0 0 0">
            <inertial pos="-0.06157942 -0.00142271 0.13513861" mass="60.08042639"
                      fullinertia="1.37742174 2.99386515 3.76085052 0.02521789 0.18565467 -0.00641869"/>
            <joint name="base" type="free"/>
            <geom type="mesh" group="1" density="0" rgba="0.7 0.7 0.7 1" mesh="base" friction="0 0 0"/>
            <body name="link_torso_0" pos="0 0 0.2805">
                <inertial pos="-0.0884841 0.00021367 4.6e-07" quat="0.443798 0.550483 -0.443815 0.55049" mass="2.24282"
                          diaginertia="0.0189253 0.0143368 0.00985172"/>
                <joint name="torso_0" pos="0 0 0" axis="1 0 0" limited="true" range="-0.349066 0.349066"/>
                <geom type="mesh" contype="0" conaffinity="0" group="1" density="0" rgba="0.7 0.7 0.7 1" mesh="LINK_1"/>
                <body name="link_torso_1">
                    <inertial pos="0.00728955 -0.0172852 0.0691138" quat="0.997768 -0.0453891 0.0382115 -0.0306483"
                              mass="9.72163" diaginertia="0.149421 0.139376 0.0275059"/>
                    <joint name="torso_1" pos="0 0 0" axis="0 1 0" limited="true" range="-1.0472 1.52173"/>
                    <geom type="mesh" contype="0" conaffinity="0" group="1" density="0" rgba="0.7 0.7 0.7 1"
                          mesh="LINK_2"/>
                    <body name="link_torso_2" pos="0 0 0.35">
                        <inertial pos="0.00653835 -0.0176954 0.0563658" quat="0.99687 -0.052526 0.0433482 -0.0401474"
                                  mass="9.21692" diaginertia="0.12242 0.116748 0.0292915"/>
                        <joint name="torso_2" pos="0 0 0" axis="0 1 0" limited="true" range="-2.44346 1.5708"/>
                        <geom type="mesh" contype="0" conaffinity="0" group="1" density="0" rgba="0.7 0.7 0.7 1"
                              mesh="LINK_3"/>
                        <body name="link_torso_3" pos="0 0 0.35">
                            <inertial pos="-0.00574156 -0.0172598 5.61e-05" quat="0.0913806 0.682262 -0.18841 0.700478"
                                      mass="4.18679" diaginertia="0.00955618 0.00946572 0.00832635"/>
                            <joint name="torso_3" pos="0 0 0" axis="0 1 0" limited="true" range="-0.785398 1.5708"/>
                            <geom type="mesh" contype="0" conaffinity="0" group="1" density="0" rgba="0.7 0.7 0.7 1"
                                  mesh="LINK_4"/>
                            <body name="link_torso_4">
                                <inertial pos="-0.0909709 5.085e-05 0.0260195"
                                          quat="-0.0536434 0.4399 -0.0270045 0.896036"
                                          mass="4.45566" diaginertia="0.0255574 0.0255082 0.00942882"/>
                                <joint name="torso_4" pos="0 0 0" axis="1 0 0" limited="true"
                                       range="-0.523599 0.523599"/>
                                <geom type="mesh" contype="0" conaffinity="0" group="1" density="0" rgba="0.7 0.7 0.7 1"
                                      mesh="LINK_5"/>
                                <body name="link_torso_5" pos="0 0 0.309427">
                                    <inertial pos="-0.0240609 0.00153804 -0.0324788"
                                              quat="0.998213 0.00351548 -0.0531835 0.0270014" mass="12.8782"
                                              diaginertia="0.19169 0.155257 0.133022"/>
                                    <joint name="torso_5" pos="0 0 0" axis="0 0 1" limited="true"
                                           range="-1.5708 1.5708"/>
                                    <geom type="mesh" contype="0" conaffinity="0" group="1" density="0"
                                          rgba="0.7 0.7 0.7 1"
                                          mesh="LINK_6"/>
                                    <body name="link_right_arm_0" pos="0 -0.22 0.0800735" quat="0.984808 -0.173648 0 0">
                                        <inertial pos="-0.00316662 0.0343718 -3e-07"
                                                  quat="0.536676 0.553304 0.439546 0.461122" mass="1.26164"
                                                  diaginertia="0.00433912 0.00432154 0.00223129"/>
                                        <joint name="right_arm_0" pos="0 0 0" axis="0 1 0" limited="true"
                                               range="-2.35619 2.35619"/>
                                        <geom type="mesh" contype="0" conaffinity="0" group="1" density="0"
                                              rgba="0.7 0.7 0.7 1" mesh="LINK_7"/>
                                        <body name="link_right_arm_1" quat="0.984808 0.173648 0 0">
                                            <inertial pos="-0.00307855 -0.00124741 -0.0129432"
                                                      quat="0.691024 -0.061096 -0.016345 0.72006" mass="2.27287"
                                                      diaginertia="0.00447747 0.0038967 0.00286448"/>
                                            <joint name="right_arm_1" pos="0 0 0" axis="1 0 0" limited="true"
                                                   range="-3.14159 0.05"/>
                                            <geom type="mesh" contype="0" conaffinity="0" group="1" density="0"
                                                  rgba="0.7 0.7 0.7 1" mesh="LINK_8"/>
                                            <body name="link_right_arm_2">
                                                <inertial pos="0.00115434 -0.00196635 -0.161925"
                                                          quat="0.998316 -0.0390505 -0.0388849 0.0181103" mass="2.46909"
                                                          diaginertia="0.0098447 0.00928024 0.00322202"/>
                                                <joint name="right_arm_2" pos="0 0 0" axis="0 0 1" limited="true"
                                                       range="-2.0944 2.0944"/>
                                                <geom type="mesh" contype="0" conaffinity="0" group="1" density="0"
                                                      rgba="0.7 0.7 0.7 1" mesh="LINK_9"/>
                                                <body name="link_right_arm_3" pos="0.031 0 -0.276">
                                                    <inertial pos="-0.0160313 -0.00692891 -0.0454981"
                                                              quat="0.950945 0.0932571 0.100342 0.277377" mass="2.26099"
                                                              diaginertia="0.0086724 0.00849326 0.00187523"/>
                                                    <joint name="right_arm_3" pos="0 0 0" axis="0 1 0" limited="true"
                                                           range="-2.61799 0.01"/>
                                                    <geom type="mesh" contype="0" conaffinity="0" group="1" density="0"
                                                          rgba="0.7 0.7 0.7 1" mesh="LINK_10"/>
                                                    <body name="link_right_arm_4" pos="-0.031 0 -0.256">
                                                        <inertial pos="-1.1e-07 -0.0269604 0.0618211"
                                                                  quat="0.686909 -0.167796 0.167796 0.686909"
                                                                  mass="0.425087"
                                                                  diaginertia="0.000885625 0.00082466 0.000266295"/>
                                                        <joint name="right_arm_4" pos="0 0 0" axis="0 0 1"
                                                               limited="true"
                                                               range="-6.28319 6.28319"/>
                                                        <geom type="mesh" contype="0" conaffinity="0" group="1"
                                                              density="0"
                                                              rgba="0.7 0.7 0.7 1" mesh="LINK_11"/>
                                                        <body name="link_right_arm_5">
                                                            <inertial pos="0.00318034 -0.00532264 -0.0280966"
                                                                      quat="0.559407 0.0608226 -0.0803636 0.822743"
                                                                      mass="1.59194"
                                                                      diaginertia="0.00262685 0.00255036 0.00151658"/>
                                                            <joint name="right_arm_5" pos="0 0 0" axis="0 1 0"
                                                                   limited="true" range="-1.74533 2.00713"/>
                                                            <geom type="mesh" contype="0" conaffinity="0" group="1"
                                                                  density="0" rgba="0.7 0.7 0.7 1" mesh="LINK_12"/>
                                                            <body name="link_right_arm_6">
                                                                <inertial pos="0.000121728 -5.16746e-05 -0.112461"
                                                                          quat="0.998072 -0.0614529 -0.00470894 0.00726149"
                                                                          mass="1.23267"
                                                                          diaginertia="0.00317453 0.00283703 0.00155214"/>
                                                                <joint name="right_arm_6" pos="0 0 0" axis="0 0 1"
                                                                       limited="true" range="-2.96706 2.96706"/>
                                                                <geom type="mesh" contype="0" conaffinity="0" group="1"
                                                                      density="0" rgba="0.7 0.7 0.7 1" mesh="LINK_13"/>
                                                                <site name="ee_right" pos="0 0 -0.1087"/>
                                                                <geom pos="0 0 -0.1087" type="mesh" contype="0"
                                                                      conaffinity="0" group="1" density="0"
                                                                      rgba="0.7 0.7 0.7 1" mesh="EE_BODY"/>
                                                                <geom pos="0.005 0 -0.2278" type="mesh" contype="0"
                                                                      conaffinity="0" group="1" density="0"
                                                                      rgba="0.7 0.7 0.7 1" mesh="EE_FINGER"/>
                                                                <geom pos="-0.005 0 -0.2278" quat="4.48966e-11 0 0 1"
                                                                      type="mesh" contype="0" conaffinity="0" group="1"
                                                                      density="0" rgba="0.7 0.7 0.7 1"
                                                                      mesh="EE_FINGER"/>
                                                            </body>
                                                        </body>
                                                    </body>
                                                </body>
                                            </body>
                                        </body>
                                    </body>
                                    <body name="link_left_arm_0" pos="0 0.22 0.0800735" quat="0.984808 0.173648 0 0">
                                        <inertial pos="-0.00316662 -0.0343715 2.42e-06"
                                                  quat="0.441442 0.459281 0.538276 0.551768" mass="1.26164"
                                                  diaginertia="0.0043391 0.00432158 0.00223133"/>
                                        <joint name="left_arm_0" pos="0 0 0" axis="0 1 0" limited="true"
                                               range="-2.35619 2.35619"/>
                                        <geom type="mesh" contype="0" conaffinity="0" group="1" density="0"
                                              rgba="0.7 0.7 0.7 1" mesh="LINK_14"/>
                                        <body name="link_left_arm_1" quat="0.984808 -0.173648 0 0">
                                            <inertial pos="-0.0018347 0.00040596 -0.0100873"
                                                      quat="0.701113 -0.0246572 -0.049881 0.710875" mass="1.88139"
                                                      diaginertia="0.00355382 0.00296561 0.0022966"/>
                                            <joint name="left_arm_1" pos="0 0 0" axis="1 0 0" limited="true"
                                                   range="-0.05 3.14159"/>
                                            <geom type="mesh" contype="0" conaffinity="0" group="1" density="0"
                                                  rgba="0.7 0.7 0.7 1" mesh="LINK_15"/>
                                            <body name="link_left_arm_2">
                                                <inertial pos="0.00066086 -0.00038583 -0.15743"
                                                          quat="0.999413 -0.00635373 -0.0335732 -0.00246859"
                                                          mass="2.35634"
                                                          diaginertia="0.00845197 0.00802394 0.00293109"/>
                                                <joint name="left_arm_2" pos="0 0 0" axis="0 0 1" limited="true"
                                                       range="-2.0944 2.0944"/>
                                                <geom type="mesh" contype="0" conaffinity="0" group="1" density="0"
                                                      rgba="0.7 0.7 0.7 1" mesh="LINK_16"/>
                                                <body name="link_left_arm_3" pos="0.031 0 -0.276">
                                                    <inertial pos="-0.015653 0.00793126 -0.0499794"
                                                              quat="0.977098 -0.0897025 0.113811 -0.15582"
                                                              mass="2.00906"
                                                              diaginertia="0.00798526 0.00783637 0.00146823"/>
                                                    <joint name="left_arm_3" pos="0 0 0" axis="0 1 0" limited="true"
                                                           range="-2.61799 0.01"/>
                                                    <geom type="mesh" contype="0" conaffinity="0" group="1" density="0"
                                                          rgba="0.7 0.7 0.7 1" mesh="LINK_17"/>
                                                    <body name="link_left_arm_4" pos="-0.031 0 -0.256">
                                                        <inertial pos="1.1e-07 0.0269604 0.0618211"
                                                                  quat="0.686909 0.167796 -0.167796 0.686909"
                                                                  mass="0.425087"
                                                                  diaginertia="0.000885625 0.00082466 0.000266295"/>
                                                        <joint name="left_arm_4" pos="0 0 0" axis="0 0 1" limited="true"
                                                               range="-6.28319 6.28319"/>
                                                        <geom type="mesh" contype="0" conaffinity="0" group="1"
                                                              density="0"
                                                              rgba="0.7 0.7 0.7 1" mesh="LINK_18"/>
                                                        <body name="link_left_arm_5">
                                                            <inertial pos="0.00340082 0.00576824 -0.0250731"
                                                                      quat="0.874666 -0.0845974 0.0492323 0.474742"
                                                                      mass="1.44265"
                                                                      diaginertia="0.00238544 0.00231489 0.00134498"/>
                                                            <joint name="left_arm_5" pos="0 0 0" axis="0 1 0"
                                                                   limited="true"
                                                                   range="-1.74533 2.00713"/>
                                                            <geom type="mesh" contype="0" conaffinity="0" group="1"
                                                                  density="0" rgba="0.7 0.7 0.7 1" mesh="LINK_19"/>
                                                            <body name="link_left_arm_6">
                                                                <inertial pos="-0.000121728 5.16746e-05 -0.112461"
                                                                          quat="0.997975 -0.0629359 -0.00688517 0.00606201"
                                                                          mass="1.23267"
                                                                          diaginertia="0.00317468 0.00283802 0.001551"/>
                                                                <joint name="left_arm_6" pos="0 0 0" axis="0 0 1"
                                                                       limited="true" range="-2.96706 2.96706"/>
                                                                <geom type="mesh" contype="0" conaffinity="0" group="1"
                                                                      density="0" rgba="0.7 0.7 0.7 1" mesh="LINK_20"/>
                                                                <site name="ee_left" pos="0 0 -0.1087"/>
                                                                <geom pos="0 0 -0.1087" type="mesh" contype="0"
                                                                      conaffinity="0" group="1" density="0"
                                                                      rgba="0.7 0.7 0.7 1" mesh="EE_BODY"/>
                                                                <geom pos="0.005 0 -0.2278" type="mesh" contype="0"
                                                                      conaffinity="0" group="1" density="0"
                                                                      rgba="0.7 0.7 0.7 1" mesh="EE_FINGER"/>
                                                                <geom pos="-0.005 0 -0.2278" quat="4.48966e-11 0 0 1"
                                                                      type="mesh" contype="0" conaffinity="0" group="1"
                                                                      density="0" rgba="0.7 0.7 0.7 1"
                                                                      mesh="EE_FINGER"/>
                                                            </body>
                                                        </body>
                                                    </body>
                                                </body>
                                            </body>
                                        </body>
                                    </body>
                                    <body name="link_head_0" pos="0 0 0.14">
                                        <inertial pos="0 0 0" quat="1 0 0 0" mass="1" diaginertia="0.000001 0.000001 0.000001"/>
                                        <joint name="head_0" pos="0 0 0" axis="0 0 1" limited="true" range="-0.523 0.523"/>
                                        <body name="link_head_1" pos="0 0 0">
                                            <inertial pos="0 0 0" quat="1 0 0 0" mass="1" diaginertia="0.000001 0.000001 0.000001"/>
                                            <joint name="head_1" pos="0 0 0" axis="0 1 0" limited="true" range="-0.35 1.57"/>
                                        </body>
                                    </body>
                                </body>
                            </body>
                        </body>
                    </body>
                </body>
            </body>
            <body name="wheel_r" pos="0.228 -0.265 0.1">
                <inertial pos="0 -0.00073938 0" quat="0.707107 0 0 0.707107" mass="1.37784"
                          diaginertia="0.00811815 0.00426657 0.00426657"/>
                <joint name="right_wheel" pos="0 0 0" axis="0 1 0" limited="false"/>
                <geom type="mesh" group="1" density="0" rgba="0.7 0.7 0.7 1" mesh="WHEEL" friction="1 0.01 5"/>
            </body>
            <body name="wheel_l" pos="0.228 0.265 0.1">
                <inertial pos="0 0.00073938 0" quat="0.707107 0 0 0.707107" mass="1.37784"
                          diaginertia="0.00811815 0.00426657 0.00426657"/>
                <joint name="left_wheel" pos="0 0 0" axis="0 1 0" limited="false"/>
                <geom type="mesh" group="1" density="0" rgba="0.7 0.7 0.7 1" mesh="WHEEL" friction="1 0.01 5"/>
            </body>
        </body>
    </worldbody>

    <actuator>
        <motor name="left_wheel_act" joint="left_wheel"/>
        <motor name="right_wheel_act" joint="right_wheel"/>

        <motor name="link1_act" joint="torso_0"/>
        <motor name="link2_act" joint="torso_1"/>
        <motor name="link3_act" joint="torso_2"/>
        <motor name="link4_act" joint="torso_3"/>
        <motor name="link5_act" joint="torso_4"/>
        <motor name="link6_act" joint="torso_5"/>

        <motor name="left_arm_1_act" joint="left_arm_0"/>
        <motor name="left_arm_2_act" joint="left_arm_1"/>
        <motor name="left_arm_3_act" joint="left_arm_2"/>
        <motor name="left_arm_4_act" joint="left_arm_3"/>
        <motor name="left_arm_5_act" joint="left_arm_4"/>
        <motor name="left_arm_6_act" joint="left_arm_5"/>
        <motor name="left_arm_7_act" joint="left_arm_6"/>

        <motor name="right_arm_1_act" joint="right_arm_0"/>
        <motor name="right_arm_2_act" joint="right_arm_1"/>
        <motor name="right_arm_3_act" joint="right_arm_2"/>
        <motor name="right_arm_4_act" joint="right_arm_3"/>
        <motor name="right_arm_5_act" joint="right_arm_4"/>
        <motor name="right_arm_6_act" joint="right_arm_5"/>
        <motor name="right_arm_7_act" joint="right_arm_6"/>

        <motor name="head_0_act" joint="head_0"/>
        <motor name="head_1_act" joint="head_1"/>
    </actuator>
</mujoco>
