<?xml version="1.0"?>
<robot name="RB_Y1_V1.0.1">
    <mobile type="differential" xyz="0.228 0 0" rpy="0 0 0" joints="right_wheel left_wheel"
            params="0.53 0.1"/> <!-- wheel_base, wheel_radius -->

    <link name="base">
        <inertial>
            <mass value="60.08042639"/>
            <origin rpy="0 0 0" xyz="-0.06157942 -0.00142271 0.13513861"/>
            <inertia ixx="1.37742174" ixy="0.02521789" ixz="0.18565467" iyy="2.99386515" iyz="-0.00641869"
                     izz="3.76085052"/>
        </inertial>

        <visual>
            <geometry>
                <mesh filename="./meshes/base.dae"/>
            </geometry>
        </visual>
    </link>

    <link name="wheel_r">
        <inertial>
            <mass value="1.37783736"/>
            <origin rpy="0 0 0" xyz="0.0 -0.00073938 0.0"/>
            <inertia ixx="0.00426657" ixy="0.0" ixz="0.0" iyy="0.00811815" iyz="0.0" izz="0.00426657"/>
        </inertial>

        <visual>
            <geometry>
                <mesh filename="./meshes/WHEEL.dae"/>
            </geometry>
        </visual>
    </link>

    <link name="wheel_l">
        <inertial>
            <mass value="1.37783736"/>
            <origin rpy="0 0 0" xyz="0.0 0.00073938 0.0"/>
            <inertia ixx="0.00426657" ixy="0.0" ixz="0.0" iyy="0.00811815" iyz="0.0" izz="0.00426657"/>
        </inertial>

        <visual>
            <geometry>
                <mesh filename="./meshes/WHEEL.dae"/>
            </geometry>
        </visual>
    </link>

    <link name="link_torso_0">
        <inertial>
            <mass value="2.24282123"/>
            <origin rpy="0 0 0" xyz="-0.08848415 0.00021367 0.00000046"/>
            <inertia ixx="0.01413496" ixy="0.00092982" ixz="-0.00000010" iyy="0.01005357"
                     iyz="-0.00000008" izz="0.01892525"/>
        </inertial>

        <visual>
            <geometry>
                <mesh filename="./meshes/LINK_1.dae"/>
            </geometry>
        </visual>

        <collision>
            <origin xyz="-0.115 0 0" rpy="0 1.5708 0"/>
            <geometry>
                <capsule radius="0.105" length="0.230" coltype="1"/>
                <!-- <capsule sp="0.0 0.0 0.0" ep="-0.230 0.0 0.0" radius="0.105" length="1"/> -->
            </geometry>
        </collision>
    </link>

    <link name="link_torso_1">
        <inertial>
            <mass value="9.72162676"/>
            <origin rpy="0 0 0" xyz="0.00728955 -0.01728522 0.06911380"/>
            <inertia ixx="0.14862640" ixy="-0.00142621" ixz="-0.00951385" iyy="0.13854733"
                     iyz="-0.00975351" izz="0.02912982"/>
        </inertial>

        <visual>
            <geometry>
                <mesh filename="./meshes/LINK_2.dae"/>
            </geometry>
        </visual>

        <collision>
            <origin xyz="0.0100 0 0.2400" rpy="0 0 0"/>
            <geometry>
                <capsule radius="0.115" length="0.220" coltype="2"/>
                <!-- <capsule sp="0.01 0.0 0.130" ep="0.01 0.0 0.350" radius="0.115"/> -->
            </geometry>
        </collision>
    </link>

    <link name="link_torso_2">
        <inertial>
            <mass value="9.21691850"/>
            <origin rpy="0 0 0" xyz="0.00653835 -0.01769536 0.05636582"/>
            <inertia ixx="0.12162270" ixy="-0.00127910" ixz="-0.00831678" iyy="0.11589190"
                     iyz="-0.00873271" izz="0.03094484"/>
        </inertial>

        <visual>
            <geometry>
                <mesh filename="./meshes/LINK_3.dae"/>
            </geometry>
        </visual>

        <collision>
            <origin xyz="0.0250 0 0.2300" rpy="0 0 0"/>
            <geometry>
                <capsule radius="0.095" length="0.1600" coltype="4"/>
                <!-- <capsule sp="0.025 0.0 0.15" ep="0.025 0.0 0.310" radius="0.095"/> -->
            </geometry>
        </collision>
    </link>

    <link name="link_torso_3">
        <inertial>
            <mass value="4.18679196"/>
            <origin rpy="0 0 0" xyz="-0.00574156 -0.01725975 0.00005610"/>
            <inertia ixx="0.00849870" ixy="0.00040861" ixz="-0.00000263" iyy="0.00929513"
                     iyz="-0.00001243" izz="0.00955442"/>
        </inertial>

        <visual>
            <geometry>
                <mesh filename="./meshes/LINK_4.dae"/>
            </geometry>
        </visual>
    </link>

    <link name="link_torso_4">
        <inertial>
            <mass value="4.45566276"/>
            <origin rpy="0 0 0" xyz="-0.09097095 0.00005085 0.02601950"/>
            <inertia ixx="0.01545991" ixy="0.00001883" ixz="-0.00780349" iyy="0.02550888" iyz="0.00000715"
                     izz="0.01952563"/>
        </inertial>

        <visual>
            <geometry>
                <mesh filename="./meshes/LINK_5.dae"/>
            </geometry>
        </visual>


        <collision>
            <origin xyz="-0.070000 0 0.038500" rpy="0 1.5708 0"/>
            <geometry>
                <capsule radius="0.105" length="0.2" coltype="8"/>
                <!-- <capsule sp="0.03 0.0 0.0385" ep="-0.170 0.0 0.0385" radius="0.105"/> -->
            </geometry>
        </collision>
    </link>

    <link name="link_torso_5">
        <inertial>
            <mass value="12.59012341"/>
            <origin rpy="0 0 0" xyz="-0.01338376 0.00025621 -0.03272487"/>
            <inertia ixx="0.21375525" ixy="0.00051520" ixz="0.00880124" iyy="0.16562090" iyz="-0.00023995"
                     izz="0.13308879"/>
        </inertial>

        <visual>
            <geometry>
                <mesh filename="./meshes/LINK_6.dae"/>
            </geometry>
        </visual>

        <collision>
            <origin xyz="0 0 0.0075" rpy="0 0 0"/>
            <geometry>
                <capsule radius="0.155" length="0.1350" coltype="16"/>
                <!-- <capsule sp="0.0 0.0 -0.06" ep="0.0 0.0 0.075" radius="0.155"/> -->
            </geometry>
        </collision>
    </link>

    <link name="link_right_arm_0">
        <inertial>
            <mass value="1.26164242"/>
            <origin rpy="0 0 0" xyz="-0.00316662 0.03437181 -0.00000030"/>
            <inertia ixx="0.00230621" ixy="0.00039024" ixz="-0.00000256" iyy="0.00426418" iyz="0.00000118"
                     izz="0.00432156"/>
        </inertial>

        <visual>
            <geometry>
                <mesh filename="./meshes/LINK_7.dae"/>
            </geometry>
        </visual>

        <collision>
            <origin xyz="-0.015 0.018 -0.008" rpy="0 1.5708 0"/>
            <geometry>
                <capsule radius="0.075" length="0.0700"/>
            </geometry>
        </collision>
    </link>

    <link name="link_right_arm_1">
        <inertial>
            <mass value="2.27287031"/>
            <origin rpy="0 0 0" xyz="-0.00307855 -0.00124741 -0.01294324"/>
            <inertia ixx="0.00388490" ixy="-0.00001477" ixz="0.00011465" iyy="0.00447034"
                     iyz="-0.00010023" izz="0.00288341"/>
        </inertial>

        <visual>
            <geometry>
                <mesh filename="./meshes/LINK_8.dae"/>
            </geometry>
        </visual>

        <collision>
            <origin xyz="0 0 -0.1000" rpy="0 0 0"/>
            <geometry>
                <capsule radius="0.05" length="0.2" coltype="32"/>
                <!-- <capsule sp="0.0 0.0 0.0" ep="0.0 0.0 -0.200" radius="0.050"/> -->
            </geometry>
        </collision>
    </link>

    <link name="link_right_arm_2">
        <inertial>
            <mass value="2.46909439"/>
            <origin rpy="0 0 0" xyz="0.00115434 -0.00196635 -0.16192524"/>
            <inertia ixx="0.00980269" ixy="0.00005871" ixz="0.00051888" iyy="0.00924560" iyz="-0.00045932"
                     izz="0.00329867"/>
        </inertial>

        <visual>
            <geometry>
                <mesh filename="./meshes/LINK_9.dae"/>
            </geometry>
        </visual>

        <collision>
            <origin xyz="0.0260 0 -0.2760" rpy="1.5708 0 0"/>
            <geometry>
                <capsule radius="0.05" length="0.080000" coltype="64"/>
                <!-- <capsule sp="0.026 -0.040 -0.276" ep="0.026 0.040 -0.276" radius="0.05"/> -->
            </geometry>
        </collision>
    </link>

    <link name="link_right_arm_3">
        <inertial>
            <mass value="2.26099493"/>
            <origin rpy="0 0 0" xyz="-0.01603135 -0.00692891 -0.04549811"/>
            <inertia ixx="0.00822606" ixy="0.00027620" ixz="-0.00156570" iyy="0.00844870" iyz="0.00076157"
                     izz="0.00236614"/>
        </inertial>

        <visual>
            <geometry>
                <mesh filename="./meshes/LINK_10.dae"/>
            </geometry>
        </visual>

        <collision>
            <origin xyz="-0.0310 0 -0.1075" rpy="0 0 0"/>
            <geometry>
                <capsule radius="0.04" length="0.1150" coltype="128" colaffinity="30"/>
                <!-- <capsule sp="-0.031 0.0 -0.05" ep="-0.031 0.0 -0.165" radius="0.04"/> -->
            </geometry>
        </collision>
    </link>

    <link name="link_right_arm_4">
        <inertial>
            <mass value="0.42508710"/>
            <origin rpy="0 0 0" xyz="-0.00000011 -0.02696036 0.06182110"/>
            <inertia ixx="0.00082466" ixy="0.0" ixz="0.0" iyy="0.00075398" iyz="-0.00025338"
                     izz="0.00039794"/>
        </inertial>

        <visual>
            <geometry>
                <mesh filename="./meshes/LINK_11.dae"/>
            </geometry>
        </visual>

        <collision>
            <origin xyz="0 -0.038 0.0175" rpy="0 0 0"/>
            <geometry>
                <capsule radius="0.035" length="0.095" coltype="256" colaffinity="30"/>
            </geometry>
        </collision>
    </link>

    <link name="link_right_arm_5">
        <inertial>
            <mass value="1.59194395"/>
            <origin rpy="0 0 0" xyz="0.00318034 -0.00532264 -0.02809655"/>
            <inertia ixx="0.00256054" ixy="-0.00002344" ixz="-0.00001563" iyy="0.00257233"
                     iyz="0.00021608" izz="0.00156092"/>
        </inertial>

        <visual>
            <geometry>
                <mesh filename="./meshes/LINK_12.dae"/>
            </geometry>
        </visual>

        <collision>
            <origin xyz="0 0 -0.1" rpy="0 0 0"/>
            <geometry>
                <capsule radius="0.075" length="0.25" coltype="512" colaffinity="31"/>
                <!-- <capsule sp="0.0 0.0 0.002" ep="0.0 0.0 -0.050" radius="0.075"/> -->
            </geometry>
        </collision>
    </link>

    <link name="link_right_arm_6">
        <inertial>
            <mass value="0.21137279"/>
            <origin rpy="0 0 0" xyz="0.00066810 -0.00031708 -0.09636043"/>
            <inertia ixx="0.00013511" ixy="-0.00000242" ixz="-0.00000102" iyy="0.00014453"
                     iyz="0.00000094" izz="0.00025431"/>
        </inertial>

        <visual>
            <geometry>
                <mesh filename="./meshes/LINK_13.dae"/>
            </geometry>
        </visual>
    </link>

    <link name="link_left_arm_0">
        <inertial>
            <mass value="1.26164242"/>
            <origin rpy="0 0 0" xyz="-0.00316662 -0.03437151 0.00000242"/>
            <inertia ixx="0.00230624" ixy="-0.00039022" ixz="0.00000269" iyy="0.00426418" iyz="0.00000108"
                     izz="0.00432159"/>
        </inertial>

        <visual>
            <geometry>
                <mesh filename="./meshes/LINK_14.dae"/>
            </geometry>
        </visual>

        <collision>
            <origin xyz="-0.015 -0.018 -0.008" rpy="0 1.5708 0"/>
            <geometry>
                <capsule radius="0.075" length="0.0700"/>
            </geometry>
        </collision>
    </link>

    <link name="link_left_arm_1">
        <inertial>
            <mass value="1.88138658"/>
            <origin rpy="0 0 0" xyz="-0.00183470 0.00040596 -0.01008733"/>
            <inertia ixx="0.00295838" ixy="-0.00001176" ixz="0.00006949" iyy="0.00355208" iyz="0.00004467"
                     izz="0.00230558"/>
        </inertial>

        <visual>
            <geometry>
                <mesh filename="./meshes/LINK_15.dae"/>
            </geometry>
        </visual>

        <collision>
            <origin xyz="0 0 -0.1000" rpy="0 0 0"/>
            <geometry>
                <capsule radius="0.050" length="0.2000" colaffinity="768"/>
            </geometry>
        </collision>
    </link>

    <link name="link_left_arm_2">
        <inertial>
            <mass value="2.35634437"/>
            <origin rpy="0 0 0" xyz="0.00066086 -0.00038583 -0.15742972"/>
            <inertia ixx="0.00842712" ixy="0.00000247" ixz="0.00036948" iyy="0.00802311" iyz="-0.00006550"
                     izz="0.00295678"/>
        </inertial>

        <visual>
            <geometry>
                <mesh filename="./meshes/LINK_16.dae"/>
            </geometry>
        </visual>

        <collision>
            <origin xyz="0.0260 0 -0.2760" rpy="1.5708 0 0"/>
            <geometry>
                <capsule radius="0.05" length="0.080000" colaffinity="768"/>
            </geometry>
        </collision>
    </link>

    <link name="link_left_arm_3">
        <inertial>
            <mass value="2.00905891"/>
            <origin rpy="0 0 0" xyz="-0.01565298 0.00793126 -0.04997943"/>
            <inertia ixx="0.00756474" ixy="-0.00026771" ixz="-0.00155419" iyy="0.00772758"
                     iyz="-0.00084364" izz="0.00199754"/>
        </inertial>

        <visual>
            <geometry>
                <mesh filename="./meshes/LINK_17.dae"/>
            </geometry>
        </visual>

        <collision>
            <origin xyz="-0.0310 0 -0.1075" rpy="0 0 0"/>
            <geometry>
                <capsule radius="0.04" length="0.1150" colaffinity="926"/>
            </geometry>
        </collision>
    </link>

    <link name="link_left_arm_4">
        <inertial>
            <mass value="0.42508710"/>
            <origin rpy="0 0 0" xyz="0.00000011 0.02696036 0.06182110"/>
            <inertia ixx="0.00082466" ixy="0.0" ixz="0.0" iyy="0.00075398" iyz="0.00025338"
                     izz="0.00039794"/>
        </inertial>

        <visual>
            <geometry>
                <mesh filename="./meshes/LINK_18.dae"/>
            </geometry>
        </visual>

        <collision>
            <origin xyz="0 0.038000 0.017500" rpy="0 0 0"/>
            <geometry>
                <capsule radius="0.035" length="0.095000" colaffinity="1022"/>
            </geometry>
        </collision>
    </link>

    <link name="link_left_arm_5">
        <inertial>
            <mass value="1.44264795"/>
            <origin rpy="0 0 0" xyz="0.00340082 0.00576824 -0.02507309"/>
            <inertia ixx="0.00233577" ixy="0.00003048" ixz="-0.00001191" iyy="0.00232580"
                     iyz="-0.00019491" izz="0.00138375"/>
        </inertial>

        <visual>
            <geometry>
                <mesh filename="./meshes/LINK_19.dae"/>
            </geometry>
        </visual>

        <collision>
            <origin xyz="0 0 -0.1" rpy="0 0 0"/>
            <geometry>
                <capsule radius="0.075" length="0.25" colaffinity="1023"/>
            </geometry>
        </collision>
    </link>

    <link name="link_left_arm_6">
        <inertial>
            <mass value="0.21137279"/>
            <origin rpy="0 0 0" xyz="-0.00066810 0.00031708 -0.09636043"/>
            <inertia ixx="0.00013511" ixy="-0.00000242" ixz="0.00000102" iyy="0.00014453"
                     iyz="-0.00000094" izz="0.00025431"/>
        </inertial>

        <visual>
            <geometry>
                <mesh filename="./meshes/LINK_20.dae"/>
            </geometry>
        </visual>
    </link>

    <link name="FT_sensor_R">
        <inertial>
            <mass value="0.49078507"/>
            <origin rpy="0 0 0" xyz="0.00010423 0.00108019 -0.01880676"/>
            <inertia ixx="0.00028587" ixy="-0.00000146" ixz="-0.00000026" iyy="0.00030459"
                     iyz="-0.00000772" izz="0.00036377"/>
        </inertial>

        <visual>
            <geometry>
                <mesh filename="./meshes/FT_SENSOR_R.dae"/>
            </geometry>
        </visual>
    </link>

    <link name="FT_sensor_L">
        <inertial>
            <mass value="0.49078507"/>
            <origin rpy="0 0 0" xyz="-0.00010423 -0.00108019 -0.01880676"/>
            <inertia ixx="0.00028587" ixy="-0.00000146" ixz="0.00000026" iyy="0.00030459" iyz="0.00000772"
                     izz="0.00036377"/>
        </inertial>

        <visual>
            <geometry>
                <mesh filename="./meshes/FT_SENSOR_L.dae"/>
            </geometry>
        </visual>
    </link>

    <link name="ee_right">
        <inertial>
            <mass value="0.46704998"/>
            <origin rpy="0 0 0" xyz="0.00212703 0.00000615 -0.04287176"/>
            <inertia ixx="0.00032067" ixy="0.00002383" ixz="-0.00000785" iyy="0.00059559"
                     iyz="-0.00000007" izz="0.00052732"/>
        </inertial>

        <visual>
            <geometry>
                <mesh filename="./meshes/EE_BODY.dae"/>
            </geometry>
        </visual>
    </link>

    <link name="ee_finger_r1">
        <inertial>
            <mass value="0.03326999"/>
            <origin rpy="0 0 0" xyz="0.00278346 -0.00000329 -0.02570112"/>
            <inertia ixx="0.00001231" ixy="0.0" ixz="-0.00000042" iyy="0.00001066" iyz="0.0"
                     izz="0.00000224"/>
        </inertial>

        <visual>
            <geometry>
                <mesh filename="./meshes/EE_FINGER.dae"/>
            </geometry>
        </visual>
    </link>

    <link name="ee_finger_r2">
        <inertial>
            <mass value="0.03326999"/>
            <origin rpy="0 0 0" xyz="0.00278346 -0.00000329 -0.02570112"/>
            <inertia ixx="0.00001231" ixy="0.0" ixz="-0.00000042" iyy="0.00001066" iyz="0.0"
                     izz="0.00000224"/>
        </inertial>

        <visual>
            <geometry>
                <mesh filename="./meshes/EE_FINGER.dae"/>
            </geometry>
        </visual>
    </link>

    <link name="ee_left">
        <inertial>
            <mass value="0.46704998"/>
            <origin rpy="0 0 0" xyz="0.00212703 0.00000615 -0.04287176"/>
            <inertia ixx="0.00032067" ixy="0.00002383" ixz="-0.00000785" iyy="0.00059559"
                     iyz="-0.00000007" izz="0.00052732"/>
        </inertial>

        <visual>
            <geometry>
                <mesh filename="./meshes/EE_BODY.dae"/>
            </geometry>
        </visual>
    </link>

    <link name="ee_finger_l1">
        <inertial>
            <mass value="0.03326999"/>
            <origin rpy="0 0 0" xyz="0.00278346 -0.00000329 -0.02570112"/>
            <inertia ixx="0.00001231" ixy="0.0" ixz="-0.00000042" iyy="0.00001066" iyz="0.0"
                     izz="0.00000224"/>
        </inertial>

        <visual>
            <geometry>
                <mesh filename="./meshes/EE_FINGER.dae"/>
            </geometry>
        </visual>
    </link>

    <link name="ee_finger_l2">
        <inertial>
            <mass value="0.03326999"/>
            <origin rpy="0 0 0" xyz="0.00278346 -0.00000329 -0.02570112"/>
            <inertia ixx="0.00001231" ixy="0.0" ixz="-0.00000042" iyy="0.00001066" iyz="0.0"
                     izz="0.00000224"/>
        </inertial>

        <visual>
            <geometry>
                <mesh filename="./meshes/EE_FINGER.dae"/>
            </geometry>
        </visual>
    </link>

    <link name="link_head_0">
        <inertial>
            <mass value="0.07582110"/>
            <origin rpy="0 0 0" xyz="-0.00800549 0.0 -0.01100308"/>
            <inertia ixx="0.00003307" ixy="0.0" ixz="-0.00000290" iyy="0.00002209" iyz="0.0"
                     izz="0.00003796"/>
        </inertial>

        <visual>
            <geometry>
                <mesh filename="./meshes/PAN_TILT_1.dae"/>
            </geometry>
        </visual>
    </link>

    <link name="link_head_1">
        <inertial>
            <mass value="0.07450580"/>
            <origin rpy="0 0 0" xyz="-0.01150679 -0.00114270 -0.00031579"/>
            <inertia ixx="0.00001850" ixy="-0.00000035" ixz="0.00000203" iyy="0.00002451"
                     iyz="-0.00000010" izz="0.00002062"/>
        </inertial>

        <visual>
            <geometry>
                <mesh filename="./meshes/PAN_TILT_2.dae"/>
            </geometry>
        </visual>
    </link>

    <link name="link_head_2">
        <inertial>
            <mass value="0.03585374"/>
            <origin rpy="0 0 0" xyz="-0.00081966 0.00099024 0.02283704"/>
            <inertia ixx="0.00002046" ixy="0.00000001" ixz="-0.00000027" iyy="0.00001044" iyz="0.00000076"
                     izz="0.00001291"/>
        </inertial>

        <visual>
            <geometry>
                <mesh filename="./meshes/PAN_TILT_3.dae"/>
            </geometry>
        </visual>
    </link>


    <!-- Joints -->
    <joint name="right_wheel" type="continuous">
        <parent link="base"/>
        <child link="wheel_r"/>
        <origin rpy="0.0 0.0 0.0" xyz="0.228 -0.265 0.1"/>
        <axis xyz="0 -1 0"/>
        <limit velocity="15.707963268" acceleration="3.141592"/>
    </joint>

    <joint name="left_wheel" type="continuous">
        <parent link="base"/>
        <child link="wheel_l"/>
        <origin rpy="0.0 0.0 0.0" xyz="0.228 0.265 0.1"/>
        <axis xyz="0 -1 0"/>
        <limit velocity="15.707963268" acceleration="3.141592"/>
    </joint>

    <joint name="torso_0" type="revolute">
        <parent link="base"/>
        <child link="link_torso_0"/>
        <origin rpy="0.0 0.0 0.0" xyz="0.0 0.0 0.2805"/>
        <axis xyz="1 0 0"/>
        <!-- Nm, rad/s^2, rad/s, (min) rad, (max) rad -->
        <!-- 270Nm, 5rad/s^2, 120deg/s, -15deg, 15deg -->
        <limit effort="270.0"
               acceleration="5.0"
               velocity="2.09439510"
               lower="-0.261799388"
               upper="0.261799388"
        />
    </joint>

    <joint name="torso_1" type="revolute">
        <parent link="link_torso_0"/>
        <child link="link_torso_1"/>
        <origin rpy="0.0 0.0 0.0" xyz="0.0 0.0 0.0"/>
        <axis xyz="0 1 0"/>
        <!-- Nm, rad/s^2, rad/s, (min) rad, (max) rad -->
        <!-- 270Nm, 5rad/s^2, 120deg/s, -30deg, 90deg -->
        <limit effort="270.0"
               acceleration="5.0"
               velocity="2.09439510"
               lower="-0.523598776"
               upper="1.570796327"
        />
    </joint>

    <joint name="torso_2" type="revolute">
        <parent link="link_torso_1"/>
        <child link="link_torso_2"/>
        <origin rpy="0.0 0.0 0.0" xyz="0.0 0.0 0.350"/>
        <axis xyz="0 1 0"/>
        <!-- Nm, rad/s^2, rad/s, (min) rad, (max) rad -->
        <!-- 270Nm, 5rad/s^2, 120deg/s, -150deg, 90deg -->
        <limit effort="270.0"
               acceleration="5.0"
               velocity="2.09439510"
               lower="-2.617993878"
               upper="1.570796327"
        />
    </joint>

    <joint name="torso_3" type="revolute">
        <parent link="link_torso_2"/>
        <child link="link_torso_3"/>
        <origin rpy="0.0 0.0 0.0" xyz="0.0 0.0 0.350"/>
        <axis xyz="0 1 0"/>
        <!-- Nm, rad/s^2, rad/s, (min) rad, (max) rad -->
        <!-- 120Nm, 5rad/s^2, 180deg/s, -45deg, 90deg -->
        <limit effort="120.0"
               acceleration="5.0"
               velocity="3.141592654"
               lower="-0.785398163"
               upper="1.570796327"
        />
    </joint>

    <joint name="torso_4" type="revolute">
        <parent link="link_torso_3"/>
        <child link="link_torso_4"/>
        <origin rpy="0.0 0.0 0.0" xyz="0.0 0.0 0.0"/>
        <axis xyz="1 0 0"/>
        <!-- Nm, rad/s^2, rad/s, (min) rad, (max) rad -->
        <!-- 120Nm, 5rad/s^2, 180deg/s, -30deg, 30deg -->
        <limit effort="120.0"
               acceleration="5.0"
               velocity="3.141592654"
               lower="-0.523598776"
               upper="0.523598776"
        />
    </joint>

    <joint name="torso_5" type="revolute">
        <parent link="link_torso_4"/>
        <child link="link_torso_5"/>
        <origin rpy="0.0 0.0 0.0" xyz="0.0 0.0 0.309426548461"/>
        <axis xyz="0 0 1"/>
        <!-- Nm, rad/s^2, rad/s, (min) rad, (max) rad -->
        <!-- 120Nm, 5rad/s^2, 180deg/s, -135deg, 135deg -->
        <limit effort="120.0"
               acceleration="5.0"
               velocity="3.141592654"
               lower="-2.35619449"
               upper="2.35619449"
        />
    </joint>

    <joint name="right_arm_0" type="revolute">
        <parent link="link_torso_5"/>
        <child link="link_right_arm_0"/>
        <origin rpy="-0.349065850  0.0 0.0" xyz="0.0 -0.220 0.080073451539 "/>
        <axis xyz="0 1 0"/>
        <!-- Nm, rad/s^2, rad/s, (min) rad, (max) rad -->
        <!-- 70Nm, 10rad/s^2, 180deg/s, -180deg, 180deg -->
        <limit effort="70.0"
               acceleration="10.0"
               velocity="3.141592654"
               lower="-3.141592654"
               upper="3.141592654"
        />
    </joint>

    <joint name="right_arm_1" type="revolute">
        <parent link="link_right_arm_0"/>
        <child link="link_right_arm_1"/>
        <origin rpy="0.349065850 0.0 0.0" xyz="0.0 0.0 0.0"/>
        <axis xyz="1 0 0"/>
        <!-- Nm, rad/s^2, rad/s, (min) rad, (max) rad -->
        <!-- 70Nm, 10rad/s^2, 180deg/s, -180deg, 1deg -->
        <limit effort="70.0"
               acceleration="10.0"
               velocity="3.141592654"
               lower="-3.141592654"
               upper="0.017453293"
        />
    </joint>

    <joint name="right_arm_2" type="revolute">
        <parent link="link_right_arm_1"/>
        <child link="link_right_arm_2"/>
        <origin rpy="0.0 0.0 0.0" xyz="0.0 0.0 0.0"/>
        <axis xyz="0 0 1"/>
        <!-- Nm, rad/s^2, rad/s, (min) rad, (max) rad -->
        <!-- 70Nm, 10rad/s^2, 180deg/s, -180deg, 180deg -->
        <limit effort="70.0"
               acceleration="10.0"
               velocity="3.141592654"
               lower="-3.141592654"
               upper="3.141592654"
        />
    </joint>

    <joint name="right_arm_3" type="revolute">
        <parent link="link_right_arm_2"/>
        <child link="link_right_arm_3"/>
        <origin rpy="0.0 0.0 0.0" xyz="0.031 0.0 -0.276"/>
        <axis xyz="0 1 0"/>
        <!-- Nm, rad/s^2, rad/s, (min) rad, (max) rad -->
        <!-- 40Nm, 10rad/s^2, 180deg/s, -150deg, 1deg -->
        <limit effort="40.0"
               acceleration="10.0"
               velocity="3.141592654"
               lower="-2.617993878"
               upper="0.017453293"
        />
    </joint>

    <joint name="right_arm_4" type="revolute">
        <parent link="link_right_arm_3"/>
        <child link="link_right_arm_4"/>
        <origin rpy="0.0 0.0 0.0" xyz="-0.031 0.0 -0.256"/>
        <axis xyz="0 0 1"/>
        <!-- Nm, rad/s^2, rad/s, (min) rad, (max) rad -->
        <!-- 10Nm, 10rad/s^2, 360deg/s, -180deg, 180deg -->
        <limit effort="10.0"
               acceleration="10.0"
               velocity="6.283185308"
               lower="-3.141592654"
               upper="3.141592654"
        />
    </joint>

    <joint name="right_arm_5" type="revolute">
        <parent link="link_right_arm_4"/>
        <child link="link_right_arm_5"/>
        <origin rpy="0.0 0.0 0.0" xyz="0.0 0.0 0.0"/>
        <axis xyz="0 1 0"/>
        <!-- Nm, rad/s^2, rad/s, (min) rad, (max) rad -->
        <!-- 10Nm, 10rad/s^2, 360deg/s, -90deg, 110deg -->
        <limit effort="10.0"
               acceleration="10.0"
               velocity="6.283185308"
               lower="-1.570796327"
               upper="1.919862177"
        />
    </joint>

    <joint name="right_arm_6" type="revolute">
        <parent link="link_right_arm_5"/>
        <child link="link_right_arm_6"/>
        <origin rpy="0.0 0.0 0.0" xyz="0.0 0.0 0.0"/>
        <axis xyz="0 0 1"/>
        <!-- Nm, rad/s^2, rad/s, (min) rad, (max) rad -->
        <!-- 8Nm, 10rad/s^2, 120deg/s, -155deg, 155deg -->
        <limit effort="8.0"
               acceleration="10.0"
               velocity="2.094395102"
               lower="-2.705260340"
               upper="2.705260340"
        />
    </joint>

    <joint name="left_arm_0" type="revolute">
        <parent link="link_torso_5"/>
        <child link="link_left_arm_0"/>
        <origin rpy="0.349065850  0.0 0.0" xyz="0.0 0.220 0.080073452 "/>
        <axis xyz="0 1 0"/>
        <!-- Nm, rad/s^2, rad/s, (min) rad, (max) rad -->
        <!-- 70Nm, 10rad/s^2, 180deg/s, -180deg, 180deg -->
        <limit effort="70.0"
               acceleration="10.0"
               velocity="3.141592654"
               lower="-3.141592654"
               upper="3.141592654"
        />
    </joint>

    <joint name="left_arm_1" type="revolute">
        <parent link="link_left_arm_0"/>
        <child link="link_left_arm_1"/>
        <origin rpy="-0.349065850 0.0 0.0" xyz="0.0 0.0 0.0"/>
        <axis xyz="1 0 0"/>
        <!-- Nm, rad/s^2, rad/s, (min) rad, (max) rad -->
        <!-- 70Nm, 10rad/s^2, 180deg/s, -1deg, 180deg -->
        <limit effort="70.0"
               acceleration="10.0"
               velocity="3.141592654"
               lower="-0.017453293"
               upper="3.141592654"
        />
    </joint>

    <joint name="left_arm_2" type="revolute">
        <parent link="link_left_arm_1"/>
        <child link="link_left_arm_2"/>
        <origin rpy="0.0 0.0 0.0" xyz="0.0 0.0 0.0"/>
        <axis xyz="0 0 1"/>
        <!-- Nm, rad/s^2, rad/s, (min) rad, (max) rad -->
        <!-- 70Nm, 10rad/s^2, 180deg/s, -180deg, 180deg -->
        <limit effort="70.0"
               acceleration="10.0"
               velocity="3.141592654"
               lower="-3.141592654"
               upper="3.141592654"
        />
    </joint>

    <joint name="left_arm_3" type="revolute">
        <parent link="link_left_arm_2"/>
        <child link="link_left_arm_3"/>
        <origin rpy="0.0 0.0 0.0" xyz="0.031 0.0 -0.276"/>
        <axis xyz="0 1 0"/>
        <!-- Nm, rad/s^2, rad/s, (min) rad, (max) rad -->
        <!-- 40Nm, 10rad/s^2, 180deg/s, -150deg, 1deg -->
        <limit effort="40.0"
               acceleration="10.0"
               velocity="3.141592654"
               lower="-2.617993878"
               upper="0.017453293"
        />
    </joint>

    <joint name="left_arm_4" type="revolute">
        <parent link="link_left_arm_3"/>
        <child link="link_left_arm_4"/>
        <origin rpy="0.0 0.0 0.0" xyz="-0.031 0.0 -0.256"/>
        <axis xyz="0 0 1"/>
        <!-- Nm, rad/s^2, rad/s, (min) rad, (max) rad -->
        <!-- 10Nm, 10rad/s^2, 360deg/s, -180deg, 180deg -->
        <limit effort="10.0"
               acceleration="10.0"
               velocity="6.283185308"
               lower="-3.141592654"
               upper="3.141592654"
        />
    </joint>

    <joint name="left_arm_5" type="revolute">
        <parent link="link_left_arm_4"/>
        <child link="link_left_arm_5"/>
        <origin rpy="0.0 0.0 0.0" xyz="0.0 0.0 0.0"/>
        <axis xyz="0 1 0"/>
        <!-- Nm, rad/s^2, rad/s, (min) rad, (max) rad -->
        <!-- 10Nm, 10rad/s^2, 360deg/s, -90deg, 110deg -->
        <limit effort="10.0"
               acceleration="10.0"
               velocity="6.283185308"
               lower="-1.570796327"
               upper="1.919862177"
        />
    </joint>

    <joint name="left_arm_6" type="revolute">
        <parent link="link_left_arm_5"/>
        <child link="link_left_arm_6"/>
        <origin rpy="0.0 0.0 0.0" xyz="0.0 0.0 0.0"/>
        <axis xyz="0 0 1"/>
        <!-- Nm, rad/s^2, rad/s, (min) rad, (max) rad -->
        <!-- 8Nm, 10rad/s^2, 120deg/s, -155deg, 155deg -->
        <limit effort="8.0"
               acceleration="10.0"
               velocity="2.094395102"
               lower="-2.705260340"
               upper="2.705260340"
        />
    </joint>

    <joint name="tool_right" type="fixed">
        <parent link="link_right_arm_6"/>
        <child link="FT_sensor_R"/>
        <origin rpy="0.0 0.0 0.0" xyz="0.0 0.0 -0.1087"/>
        <axis xyz="0 0 1"/>
    </joint>

    <joint name="FT_Sensor_END_right" type="fixed">
        <parent link="FT_sensor_R"/>
        <child link="ee_right"/>
        <origin rpy="0.0 0.0 0.0" xyz="0.0 0.0 -0.0461"/>
        <axis xyz="0 0 1"/>
    </joint>

    <joint name="gripper_finger_r1" type="prismatic" in_model_type="fixed">
        <parent link="ee_right"/>
        <child link="ee_finger_r1"/>
        <origin rpy="0.0 0.0 0.0" xyz="0.003 0.0 -0.073"/>
        <axis xyz="-1 0 0"/>
        <limit effort="1000" velocity="0.05" lower="-0.05" upper="0"/>
    </joint>

    <joint name="gripper_finger_r2" type="prismatic" in_model_type="fixed">
        <parent link="ee_right"/>
        <child link="ee_finger_r2"/>
        <origin rpy="0.0 0.0 3.1415926535" xyz="-0.003 0.0 -0.073"/>
        <axis xyz="1 0 0"/>
        <limit effort="1000" velocity="0.05" lower="0" upper="0.05"/>
    </joint>

    <joint name="tool_left" type="fixed">
        <parent link="link_left_arm_6"/>
        <child link="FT_sensor_L"/>
        <origin rpy="0.0 0.0 0" xyz="0.0 0.0 -0.1087"/>
        <axis xyz="0 0 1"/>
    </joint>

    <joint name="FT_Sensor_END_left" type="fixed">
        <parent link="FT_sensor_L"/>
        <child link="ee_left"/>
        <origin rpy="0.0 0.0 0.0" xyz="0.0 0.0 -0.0461"/>
        <axis xyz="0 0 1"/>
    </joint>

    <joint name="gripper_finger_l1" type="prismatic" in_model_type="fixed">
        <parent link="ee_left"/>
        <child link="ee_finger_l1"/>
        <origin rpy="0.0 0.0 0.0" xyz="0.003 0.0 -0.073"/>
        <axis xyz="-1 0 0"/>
        <limit effort="1000" velocity="0.05" lower="-0.05" upper="0"/>
    </joint>

    <joint name="gripper_finger_l2" type="prismatic" in_model_type="fixed">
        <parent link="ee_left"/>
        <child link="ee_finger_l2"/>
        <origin rpy="0.0 0.0 3.1415926535" xyz="-0.003 0.0 -0.073"/>
        <axis xyz="1 0 0"/>
        <limit effort="1000" velocity="0.05" lower="0" upper="0.05"/>
    </joint>

    <joint name="head_base" type="fixed">
        <parent link="link_torso_5"/>
        <child link="link_head_0"/>
        <origin rpy="0.0 0.0 0.0" xyz="0.022 0.0 0.120073451525"/>
        <axis xyz="0 0 1"/>
    </joint>

    <joint name="head_0" type="revolute">
        <parent link="link_head_0"/>
        <child link="link_head_1"/>
        <origin rpy="0.0 0.0 0.0" xyz="0.0 0.0 0.02"/>
        <axis xyz="0 0 1"/>
        <limit effort="1000" velocity="3.14" lower="-0.523" upper="0.523"/>
    </joint>

    <joint name="head_1" type="revolute">
        <parent link="link_head_1"/>
        <child link="link_head_2"/>
        <origin rpy="0.0 0.0 0.0" xyz="0.0 0.0 0.0"/>
        <axis xyz="0 1 0"/>
        <limit effort="1000" velocity="3.14" lower="-0.35" upper="1.57"/>
    </joint>

    <!-- <joint name="head_mount" type="fixed">
      <parent link="link_head_2"/>
      <child link="Arbitrary device"/>
      <origin rpy="0.0 0.0 0.0" xyz="0.022 0.0 0.04"/>
      <axis xyz="0 0 1"/>
    </joint> -->

</robot>